Workbook
Name asd: IF( OR(AND(AND(#REF!>=2,#REF!<=5),#REF!> 50), AND(#REF!>5,#REF!>= 20) ),1,0)
Name asd: IF( OR(AND(AND(#REF!>=2,#REF!<=5),#REF!> 50), AND(#REF!>5,#REF!>= 20) ),1,0)
Name asd: IF( OR(AND(AND(#REF!>=2,#REF!<=5),#REF!> 50), AND(#REF!>5,#REF!>= 20) ),1,0)
Name asd: IF( OR(AND(AND(#REF!>=2,#REF!<=5),#REF!> 50), AND(#REF!>5,#REF!>= 20) ),1,0)
Name asd: IF( OR(AND(AND(#REF!>=2,#REF!<=5),#REF!> 50), AND(#REF!>5,#REF!>= 20) ),1,0)
Name asd: IF( OR(AND(AND(#REF!>=2,#REF!<=5),#REF!> 50), AND(#REF!>5,#REF!>= 20) ),1,0)
Name asd: IF( OR(AND(AND(#REF!>=2,#REF!<=5),#REF!> 50), AND(#REF!>5,#REF!>= 20) ),1,0)
Name asd: IF( OR(AND(AND(#REF!>=2,#REF!<=5),#REF!> 50), AND(#REF!>5,#REF!>= 20) ),1,0)
Name asd: IF( OR(AND(AND(#REF!>=2,#REF!<=5),#REF!> 50), AND(#REF!>5,#REF!>= 20) ),1,0)
Name asd: IF( OR(AND(AND(#REF!>=2,#REF!<=5),#REF!> 50), AND(#REF!>5,#REF!>= 20) ),1,0)
Name asd: IF( OR(AND(AND(#REF!>=2,#REF!<=5),#REF!> 50), AND(#REF!>5,#REF!>= 20) ),1,0)
Name asd: IF( OR(AND(AND(#REF!>=2,#REF!<=5),#REF!> 50), AND(#REF!>5,#REF!>= 20) ),1,0)
Name asd: IF( OR(AND(AND(#REF!>=2,#REF!<=5),#REF!> 50), AND(#REF!>5,#REF!>= 20) ),1,0)
Name asd: IF( OR(AND(AND(#REF!>=2,#REF!<=5),#REF!> 50), AND(#REF!>5,#REF!>= 20) ),1,0)
Name asd: IF( OR(AND(AND(#REF!>=2,#REF!<=5),#REF!> 50), AND(#REF!>5,#REF!>= 20) ),1,0)
Name asd: IF( OR(AND(AND(#REF!>=2,#REF!<=5),#REF!> 50), AND(#REF!>5,#REF!>= 20) ),1,0)
Name asd: IF( OR(AND(AND(#REF!>=2,#REF!<=5),#REF!> 50), AND(#REF!>5,#REF!>= 20) ),1,0)
Name asd: IF( OR(AND(AND(#REF!>=2,#REF!<=5),#REF!> 50), AND(#REF!>5,#REF!>= 20) ),1,0)
Name asd: IF( OR(AND(AND(#REF!>=2,#REF!<=5),#REF!> 50), AND(#REF!>5,#REF!>= 20) ),1,0)
Name asd: IF( OR(AND(AND(#REF!>=2,#REF!<=5),#REF!> 50), AND(#REF!>5,#REF!>= 20) ),1,0)
Name asd: IF( OR(AND(AND(#REF!>=2,#REF!<=5),#REF!> 50), AND(#REF!>5,#REF!>= 20) ),1,0)
Name asd: IF( OR(AND(AND(#REF!>=2,#REF!<=5),#REF!> 50), AND(#REF!>5,#REF!>= 20) ),1,0)
Name asd: IF( OR(AND(AND(#REF!>=2,#REF!<=5),#REF!> 50), AND(#REF!>5,#REF!>= 20) ),1,0)
Name CheckDay: 진행현황_01.범위명!$B$6
Name CheckDay: 진행현황_02.범위명!$B$6
Name CheckDay: 진행현황_03.범위명!$B$6
Name CheckDay: 진행현황_04.범위명!$B$6
Name CheckDay: 진행현황_05.범위명!$B$6
Name CheckDay: 진행현황_06.범위명!$B$6
Name CheckDay: 진행현황_07.범위명!$B$6
Name CheckDay: 진행현황_08.범위명!$B$6
Name CheckDay: 진행현황_09.범위명!$B$6
Name CheckDay: 진행현황_10.범위명!$B$6
Name CheckDay: 진행현황_템플릿!$B$6
Name CheckDay: 진행현황_전체!$C$6
Name CheckDay2: 진행현황_전체!$C$6
Name EI_A: IF( OR(AND(#REF!<2,#REF!>50), AND(AND(#REF!>=2,#REF!<=5), AND(#REF!>= 20,#REF!<= 50)), AND(#REF!>5, AND(#REF!>= 1,#REF!<= 19)) ),1,0)
Name EI_A: IF( OR(AND(#REF!<2,#REF!>50), AND(AND(#REF!>=2,#REF!<=5), AND(#REF!>= 20,#REF!<= 50)), AND(#REF!>5, AND(#REF!>= 1,#REF!<= 19)) ),1,0)
Name EI_A: IF( OR(AND(#REF!<2,#REF!>50), AND(AND(#REF!>=2,#REF!<=5), AND(#REF!>= 20,#REF!<= 50)), AND(#REF!>5, AND(#REF!>= 1,#REF!<= 19)) ),1,0)
Name EI_A: IF( OR(AND(#REF!<2,#REF!>50), AND(AND(#REF!>=2,#REF!<=5), AND(#REF!>= 20,#REF!<= 50)), AND(#REF!>5, AND(#REF!>= 1,#REF!<= 19)) ),1,0)
Name EI_A: IF( OR(AND(#REF!<2,#REF!>50), AND(AND(#REF!>=2,#REF!<=5), AND(#REF!>= 20,#REF!<= 50)), AND(#REF!>5, AND(#REF!>= 1,#REF!<= 19)) ),1,0)
Name EI_A: IF( OR(AND(#REF!<2,#REF!>50), AND(AND(#REF!>=2,#REF!<=5), AND(#REF!>= 20,#REF!<= 50)), AND(#REF!>5, AND(#REF!>= 1,#REF!<= 19)) ),1,0)
Name EI_A: IF( OR(AND(#REF!<2,#REF!>50), AND(AND(#REF!>=2,#REF!<=5), AND(#REF!>= 20,#REF!<= 50)), AND(#REF!>5, AND(#REF!>= 1,#REF!<= 19)) ),1,0)
Name EI_A: IF( OR(AND(#REF!<2,#REF!>50), AND(AND(#REF!>=2,#REF!<=5), AND(#REF!>= 20,#REF!<= 50)), AND(#REF!>5, AND(#REF!>= 1,#REF!<= 19)) ),1,0)
Name EI_A: IF( OR(AND(#REF!<2,#REF!>50), AND(AND(#REF!>=2,#REF!<=5), AND(#REF!>= 20,#REF!<= 50)), AND(#REF!>5, AND(#REF!>= 1,#REF!<= 19)) ),1,0)
Name EI_A: IF( OR(AND(#REF!<2,#REF!>50), AND(AND(#REF!>=2,#REF!<=5), AND(#REF!>= 20,#REF!<= 50)), AND(#REF!>5, AND(#REF!>= 1,#REF!<= 19)) ),1,0)
Name EI_A: IF( OR(AND(#REF!<2,#REF!>50), AND(AND(#REF!>=2,#REF!<=5), AND(#REF!>= 20,#REF!<= 50)), AND(#REF!>5, AND(#REF!>= 1,#REF!<= 19)) ),1,0)
Name EI_A: IF( OR(AND(#REF!<2,#REF!>50), AND(AND(#REF!>=2,#REF!<=5), AND(#REF!>= 20,#REF!<= 50)), AND(#REF!>5, AND(#REF!>= 1,#REF!<= 19)) ),1,0)
Name EI_A: IF( OR(AND(#REF!<2,#REF!>50), AND(AND(#REF!>=2,#REF!<=5), AND(#REF!>= 20,#REF!<= 50)), AND(#REF!>5, AND(#REF!>= 1,#REF!<= 19)) ),1,0)
Name EI_A: IF( OR(AND(#REF!<2,#REF!>50), AND(AND(#REF!>=2,#REF!<=5), AND(#REF!>= 20,#REF!<= 50)), AND(#REF!>5, AND(#REF!>= 1,#REF!<= 19)) ),1,0)
Name EI_A: IF( OR(AND(#REF!<2,#REF!>50), AND(AND(#REF!>=2,#REF!<=5), AND(#REF!>= 20,#REF!<= 50)), AND(#REF!>5, AND(#REF!>= 1,#REF!<= 19)) ),1,0)
Name EI_A: IF( OR(AND(#REF!<2,#REF!>50), AND(AND(#REF!>=2,#REF!<=5), AND(#REF!>= 20,#REF!<= 50)), AND(#REF!>5, AND(#REF!>= 1,#REF!<= 19)) ),1,0)
Name EI_A: IF( OR(AND(#REF!<2,#REF!>50), AND(AND(#REF!>=2,#REF!<=5), AND(#REF!>= 20,#REF!<= 50)), AND(#REF!>5, AND(#REF!>= 1,#REF!<= 19)) ),1,0)
Name EI_A: IF( OR(AND(#REF!<2,#REF!>50), AND(AND(#REF!>=2,#REF!<=5), AND(#REF!>= 20,#REF!<= 50)), AND(#REF!>5, AND(#REF!>= 1,#REF!<= 19)) ),1,0)
Name EI_A: IF( OR(AND(#REF!<2,#REF!>50), AND(AND(#REF!>=2,#REF!<=5), AND(#REF!>= 20,#REF!<= 50)), AND(#REF!>5, AND(#REF!>= 1,#REF!<= 19)) ),1,0)
Name EI_A: IF( OR(AND(#REF!<2,#REF!>50), AND(AND(#REF!>=2,#REF!<=5), AND(#REF!>= 20,#REF!<= 50)), AND(#REF!>5, AND(#REF!>= 1,#REF!<= 19)) ),1,0)
Name EI_A: IF( OR(AND(#REF!<2,#REF!>50), AND(AND(#REF!>=2,#REF!<=5), AND(#REF!>= 20,#REF!<= 50)), AND(#REF!>5, AND(#REF!>= 1,#REF!<= 19)) ),1,0)
Name EI_A: IF( OR(AND(#REF!<2,#REF!>50), AND(AND(#REF!>=2,#REF!<=5), AND(#REF!>= 20,#REF!<= 50)), AND(#REF!>5, AND(#REF!>= 1,#REF!<= 19)) ),1,0)
Name EI_A: IF( OR(AND(#REF!<2,#REF!>50), AND(AND(#REF!>=2,#REF!<=5), AND(#REF!>= 20,#REF!<= 50)), AND(#REF!>5, AND(#REF!>= 1,#REF!<= 19)) ),1,0)
Name EI_B: IF( OR(AND(#REF!<2,#REF!>50), AND(AND(#REF!>=2,#REF!<=5), AND(#REF!>= 20,#REF!<= 50)), AND(#REF!>5, AND(#REF!>= 1,#REF!<= 19)) ),1,0)

Sheet 표지
B3: 주관기관 로고
B7: 일정관리 및 통제표 (2025년)
B9: 소제목
B13: 사 업 명: | C13: 사업명 입력
B14: 사업기간: | C14: 20XX.XX.XX ~ 20XX.XX.XX
B15: 문서코드: | C15: 프로젝트코드-범위코드-단계코드-XXX_문서명
G17: 관리부서: | H17: 부서명
G18: 버 전: | H18: Ver.X.X
G19: 작 성 자: | H19: 작성자명 및 직함
G20: 작 성 일: | H20: 20XX. XX. XX
G21: 승 인 자: | H21: 승인자명 및 직함
A29: ㈜브이웨이의 승인없이 본 문서의 전부 또는 일부에 대한 복사, 배포, 사용을 금지합니다.

Sheet 문서승인
A1: =표지!C13 -> 사업명 입력 | E1: =표지!B7 -> 일정관리 및 통제표 (2025년)
A3: 문 서 승 인
A5: 구분 | B5: 소속 | C5: 이름 | D5: 일자 | E5: 서명
A6: 승인
A7: 승인
A8: 검토
A9: 검토
A10: 작성

Sheet 제개정이력
A1: =표지!C13 -> 사업명 입력 | E1: =표지!B7 -> 일정관리 및 통제표 (2025년)
A3: 제·개정 이력
A5: 버전 | B5: 작성일자 | C5: 변경내용 1) | D5: 작성자 | E5: 검토자
A6: 1 | B6: 45658 | C6: 최초작성
A23: 1) 변경내용 : 변경이 발생되는 위치와 변경 내용을 자세히 기록(장/절)하고 변경 내용을 기술한다.

Sheet 진행현황_전체
A1: =표지!C13 -> 사업명 입력 | N1: =표지!B7 -> 일정관리 및 통제표 (2025년)
A4: 진척점검 보고서 (전체)
B6: 1. 점검마감일자 | C6: 45732
B8: 2. 전체 진행 현황
B9: - 시점 누적계획 | C9: =M30 -> 100
B10: - 시점 누적실적 | C10: =M31 -> 0.375
B11: - 계획대비 실적율 | C11: =IF(C9=0, 0, C10/C9) -> 0.00375
B13: 3. 각 범위별 상세 진행 현황
B15: 구분 | C15: 01. 구분명 | D15: 02. 구분명 | E15: 03. 구분명 | F15: 04. 구분명 | G15: 05.구분명 | H15: 06.구분명 | I15: 07.구분명 | J15: 08.구분명 | K15: 09.구분명 | L15: 10.구분명 | M15: 합계
B16: 범위별 가중치 | C16: 20 | D16: 20 | E16: 60 | F16: 0 | G16: 0 | H16: 0 | I16: 0 | J16: 0 | K16: 0 | L16: 0 | M16: =SUM(C16:L16) -> 100
B17: 범위별 시점 누적계획 | C17: =진행현황_01.범위명!J17 -> 100 | D17: =진행현황_02.범위명!J17 -> 100 | E17: =진행현황_03.범위명!$J$17 -> 100 | F17: =진행현황_04.범위명!J17 -> 100 | G17: =진행현황_05.범위명!J17 -> 100 | H17: =진행현황_06.범위명!J17 -> 100 | I17: =진행현황_07.범위명!J17 -> 100 | J17: =진행현황_08.범위명!J17 -> 100 | K17: =진행현황_09.범위명!J17 -> 100 | L17: =진행현황_10.범위명!J17 -> 100
B18: 범위별 시점 누적실적 | C18: =진행현황_01.범위명!J18 -> 1.875 | D18: =진행현황_02.범위명!J18 -> 0 | E18: =진행현황_03.범위명!$J$18 -> 0 | F18: =진행현황_04.범위명!J18 -> 0 | G18: =진행현황_05.범위명!J18 -> 0 | H18: =진행현황_06.범위명!J18 -> 0 | I18: =진행현황_07.범위명!J18 -> 0 | J18: =진행현황_08.범위명!J18 -> 0 | K18: =진행현황_09.범위명!J18 -> 0 | L18: =진행현황_10.범위명!J18 -> 0
B19: 시점 누적편차 | C19: =진행현황_01.범위명!J19 -> -98.125 | D19: =진행현황_02.범위명!J19 -> -100 | E19: =진행현황_03.범위명!$J$19 -> -100 | F19: =진행현황_04.범위명!J19 -> -100 | G19: =진행현황_05.범위명!J19 -> -100 | H19: =진행현황_06.범위명!J19 -> -100 | I19: =진행현황_07.범위명!J19 -> -100 | J19: =진행현황_08.범위명!J19 -> -100 | K19: =진행현황_09.범위명!J19 -> -100 | L19: =진행현황_10.범위명!J19 -> -100
B20: 시점 누적계획율 | C20: =진행현황_01.범위명!J20 -> 1 | D20: =진행현황_02.범위명!J20 -> 1 | E20: =진행현황_03.범위명!$J$20 -> 1 | F20: =진행현황_04.범위명!J20 -> 1 | G20: =진행현황_05.범위명!J20 -> 1 | H20: =진행현황_06.범위명!J20 -> 1 | I20: =진행현황_07.범위명!J20 -> 1 | J20: =진행현황_08.범위명!J20 -> 1 | K20: =진행현황_09.범위명!J20 -> 1 | L20: =진행현황_10.범위명!J20 -> 1
B21: 시점 누적실적율 | C21: =진행현황_01.범위명!J21 -> 0.01875 | D21: =진행현황_02.범위명!J21 -> 0 | E21: =진행현황_03.범위명!$J$21 -> 0 | F21: =진행현황_04.범위명!J21 -> 0 | G21: =진행현황_05.범위명!J21 -> 0 | H21: =진행현황_06.범위명!J21 -> 0 | I21: =진행현황_07.범위명!J21 -> 0 | J21: =진행현황_08.범위명!J21 -> 0 | K21: =진행현황_09.범위명!J21 -> 0 | L21: =진행현황_10.범위명!J21 -> 0
B22: 계획대비 실적율 | C22: =IF(C17=0, 0, C18/C17) -> 0.01875 | D22: =IF(D17=0, 0, D18/D17) -> 0 | E22: =IF(E17=0, 0, E18/E17) -> 0 | F22: =IF(F17=0, 0, F18/F17) -> 0 | G22: =IF(G17=0, 0, G18/G17) -> 0 | H22: =IF(H17=0, 0, H18/H17) -> 0 | I22: =IF(I17=0, 0, I18/I17) -> 0 | J22: =IF(J17=0, 0, J18/J17) -> 0 | ... L22: =IF(L17=0, 0, L18/L17) -> 0
B23: 계획된 태스크 수 | C23: =진행현황_01.범위명!J23 -> 80 | D23: =진행현황_02.범위명!J23 -> 80 | E23: =진행현황_03.범위명!$J$23 -> 80 | F23: =진행현황_04.범위명!J23 -> 80 | G23: =진행현황_05.범위명!J23 -> 80 | H23: =진행현황_06.범위명!J23 -> 80 | I23: =진행현황_07.범위명!J23 -> 80 | J23: =진행현황_08.범위명!J23 -> 80 | K23: =진행현황_09.범위명!J23 -> 80 | L23: =진행현황_10.범위명!J23 -> 80 | M23: =SUM(C23:L23) -> 800
B24: 진행중인 태스크 수 | C24: =진행현황_01.범위명!J24 -> 0 | D24: =진행현황_02.범위명!J24 -> 0 | E24: =진행현황_03.범위명!$J$24 -> 0 | F24: =진행현황_04.범위명!J24 -> 0 | G24: =진행현황_05.범위명!J24 -> 0 | H24: =진행현황_06.범위명!J24 -> 0 | I24: =진행현황_07.범위명!J24 -> 0 | J24: =진행현황_08.범위명!J24 -> 0 | K24: =진행현황_09.범위명!J24 -> 0 | L24: =진행현황_10.범위명!J24 -> 0 | M24: =SUM(C24:L24) -> 0
B25: 종료된 태스크 수 | C25: =진행현황_01.범위명!J25 -> 2 | D25: =진행현황_02.범위명!J25 -> 0 | E25: =진행현황_03.범위명!$J$25 -> 0 | F25: =진행현황_04.범위명!J25 -> 0 | G25: =진행현황_05.범위명!J25 -> 0 | H25: =진행현황_06.범위명!J25 -> 0 | I25: =진행현황_07.범위명!J25 -> 0 | J25: =진행현황_08.범위명!J25 -> 0 | K25: =진행현황_09.범위명!J25 -> 0 | L25: =진행현황_10.범위명!J25 -> 0 | M25: =SUM(C25:L25) -> 2
B26: 지연된 태스크 수 | C26: =C23-C24-C25 -> 78 | D26: =D23-D24-D25 -> 80 | E26: =E23-E24-E25 -> 80 | F26: =F23-F24-F25 -> 80 | G26: =G23-G24-G25 -> 80 | H26: =H23-H24-H25 -> 80 | I26: =I23-I24-I25 -> 80 | J26: =J23-J24-J25 -> 80 | ... L26: =L23-L24-L25 -> 80 | M26: =SUM(C26:L26) -> 798
B27: 계획된 Review 문서 | C27: =진행현황_01.범위명!J27 -> 0 | D27: =진행현황_02.범위명!J27 -> 0 | E27: =진행현황_03.범위명!$J$27 -> 0 | F27: =진행현황_04.범위명!J27 -> 0 | G27: =진행현황_05.범위명!J27 -> 0 | H27: =진행현황_06.범위명!J27 -> 0 | I27: =진행현황_07.범위명!J27 -> 0 | J27: =진행현황_08.범위명!J27 -> 0 | K27: =진행현황_09.범위명!J27 -> 0 | L27: =진행현황_10.범위명!J27 -> 0 | M27: =SUM(C27:L27) -> 0
B28: 완료된 Review 문서 | C28: =진행현황_01.범위명!J28 -> 0 | D28: =진행현황_02.범위명!J28 -> 0 | E28: =진행현황_03.범위명!$J$28 -> 0 | F28: =진행현황_04.범위명!J28 -> 0 | G28: =진행현황_05.범위명!J28 -> 0 | H28: =진행현황_06.범위명!J28 -> 0 | I28: =진행현황_07.범위명!J28 -> 0 | J28: =진행현황_08.범위명!J28 -> 0 | K28: =진행현황_09.범위명!J28 -> 0 | L28: =진행현황_10.범위명!J28 -> 0 | M28: =SUM(C28:L28) -> 0
B29: 각 단계 Review율 | C29: =진행현황_01.범위명!J29 -> 0 | D29: =진행현황_02.범위명!J29 -> 0 | E29: =진행현황_03.범위명!J29 -> 0 | F29: =진행현황_04.범위명!J29 -> 0 | G29: =진행현황_05.범위명!J29 -> 0 | H29: =진행현황_06.범위명!J29 -> 0 | I29: =진행현황_07.범위명!J29 -> 0 | J29: =진행현황_08.범위명!J29 -> 0 | K29: =진행현황_09.범위명!J29 -> 0 | L29: =진행현황_10.범위명!J29 -> 0 | M29: =IF(M27=0, 0, M28/M27) -> 0
B30: 전체 누적계획 | C30: =C17*C16/100 -> 20 | D30: =D17*D16/100 -> 20 | E30: =E17*E16/100 -> 60 | F30: =F17*F16/100 -> 0 | G30: =G17*G16/100 -> 0 | H30: =H17*H16/100 -> 0 | I30: =I17*I16/100 -> 0 | J30: =J17*J16/100 -> 0 | ... L30: =L17*L16/100 -> 0 | M30: =SUM(C30:L30) -> 100
B31: 전체 누적실적 | C31: =C18*C16/100 -> 0.375 | D31: =D18*D16/100 -> 0 | E31: =E18*E16/100 -> 0 | F31: =F18*F16/100 -> 0 | G31: =G18*G16/100 -> 0 | H31: =H18*H16/100 -> 0 | I31: =I18*I16/100 -> 0 | J31: =J18*J16/100 -> 0 | ... L31: =L18*L16/100 -> 0 | M31: =SUM(C31:L31) -> 0.375
B32: 전체 누적편차 | C32: =C31-C30 -> -19.625 | D32: =D31-D30 -> -20 | E32: =E31-E30 -> -60 | F32: =F31-F30 -> 0 | G32: =G31-G30 -> 0 | H32: =H31-H30 -> 0 | I32: =I31-I30 -> 0 | J32: =J31-J30 -> 0 | ... M32: =M31-M30 -> -99.625
B35: 4. 각 범위별 상세 진행 현황 그래프
B56: 5. 휴일 리스트 | C56: (주5일 근무제 기준, 평일에 휴일인 날)
C58: 월일 | D58: 내용
C59: 45658 | D59: 신정
C60: 45685 | D60: 설날
C61: 45686 | D61: 설날
C62: 45687 | D62: 설날
C63: 45717 | D63: 삼일절
C64: 45719 | D64: 삼일절(대체공휴일)
C65: 45778 | D65: 근로자의날
C66: 45782 | D66: 어린이날
C67: 45783 | D67: 부처님오신날
C68: 45814 | D68: 현충일
C69: 45884 | D69: 광복절
...

Sheet 진행현황_01.범위명
A1: =표지!C13 -> 사업명 입력 | J1: =표지!B7 -> 일정관리 및 통제표 (2025년)
A4: 진척점검 보고서 (01.범위명)
A6: 1. 관리책임자 | B6: 책임자
A8: 2. 전체 진행 현황
A9: - 시점 누적계획 | B9: =SUM(B17:I17) -> 100
A10: - 시점 누적실적 | B10: =SUM(B18:I18) -> 1.875
A11: - 계획대비 실적율 | B11: =IF(B9=0, 0, B10/B9) -> 0.01875
A13: 3. 각 단계별 상세 진행 현황
A15: 구분 | B15: 단계1 | C15: 단계2 | D15: 단계3 | E15: 단계4 | F15: 단계5 | G15: 단계6 | H15: 단계7 | I15: 단계8 | J15: 합계
A16: 단계별 가중치 | B16: 15 | C16: 15 | D16: 15 | E16: 15 | F16: 15 | G16: 5 | H16: 5 | I16: 15 | J16: =SUM(B16:I16) -> 100
A17: 단계별 시점 누적계획 | B17: ='진행율 입력_01.범위명'!L10 -> 15 | C17: ='진행율 입력_01.범위명'!L21 -> 15 | D17: ='진행율 입력_01.범위명'!L32 -> 15 | E17: ='진행율 입력_01.범위명'!L43 -> 15 | F17: ='진행율 입력_01.범위명'!L54 -> 15 | G17: ='진행율 입력_01.범위명'!L65 -> 5 | H17: ='진행율 입력_01.범위명'!L76 -> 5 | I17: ='진행율 입력_01.범위명'!L87 -> 15 | J17: =SUM(B17:I17) -> 100
A18: 단계별 시점 누적실적 | B18: ='진행율 입력_01.범위명'!M10 -> 1.875 | C18: ='진행율 입력_01.범위명'!M21 -> 0 | D18: ='진행율 입력_01.범위명'!M32 -> 0 | E18: ='진행율 입력_01.범위명'!M43 -> 0 | F18: ='진행율 입력_01.범위명'!M54 -> 0 | G18: ='진행율 입력_01.범위명'!M65 -> 0 | H18: ='진행율 입력_01.범위명'!M76 -> 0 | I18: ='진행율 입력_01.범위명'!M87 -> 0 | J18: =SUM(B18:I18) -> 1.875
A19: 시점 누적편차 | B19: =B18-B17 -> -13.125 | C19: =C18-C17 -> -15 | D19: =D18-D17 -> -15 | E19: =E18-E17 -> -15 | F19: =F18-F17 -> -15 | G19: =G18-G17 -> -5 | H19: =H18-H17 -> -5 | I19: =I18-I17 -> -15 | J19: =SUM(B19:I19) -> -98.125
A20: 시점 누적계획율 | B20: ='진행율 입력_01.범위명'!J10 -> 1 | C20: ='진행율 입력_01.범위명'!J21 -> 1 | D20: ='진행율 입력_01.범위명'!J32 -> 1 | E20: ='진행율 입력_01.범위명'!J43 -> 1 | F20: ='진행율 입력_01.범위명'!J54 -> 1 | G20: ='진행율 입력_01.범위명'!J65 -> 1 | H20: ='진행율 입력_01.범위명'!J76 -> 1 | I20: ='진행율 입력_01.범위명'!J87 -> 1 | J20: =IF(J16=0, 0, J17/J16) -> 1
A21: 시점 누적실적율 | B21: ='진행율 입력_01.범위명'!K10 -> 0.125 | C21: ='진행율 입력_01.범위명'!K21 -> 0 | D21: ='진행율 입력_01.범위명'!K32 -> 0 | E21: ='진행율 입력_01.범위명'!K43 -> 0 | F21: ='진행율 입력_01.범위명'!K54 -> 0 | G21: ='진행율 입력_01.범위명'!K65 -> 0 | H21: ='진행율 입력_01.범위명'!K76 -> 0 | I21: ='진행율 입력_01.범위명'!K87 -> 0 | J21: =IF(J16=0, 0, J18/J16) -> 0.01875
A22: 계획대비 실적율 | B22: =IF(B17=0, 0, B18/B17) -> 0.125 | C22: =IF(C17=0,0,C18/C17) -> 0 | D22: =IF(D17=0, 0, D18/D17) -> 0 | E22: =IF(E17=0, 0, E18/E17) -> 0 | F22: =IF(F17=0, 0, F18/F17) -> 0 | G22: =IF(G17=0, 0, G18/G17) -> 0 | H22: =IF(H17=0, 0, H18/H17) -> 0 | I22: =IF(I17=0, 0, I18/I17) -> 0 | J22: =IF(J17=0, 0, J18/J17) -> 0.01875
A23: 계획된 태스크 수 | B23: =COUNTIF('진행율 입력_01.범위명'!J11:J20,">0") -> 10 | C23: =COUNTIF('진행율 입력_01.범위명'!J22:J31,">0") -> 10 | D23: =COUNTIF('진행율 입력_01.범위명'!J33:J42,">0") -> 10 | E23: =COUNTIF('진행율 입력_01.범위명'!J44:J53,">0") -> 10 | F23: =COUNTIF('진행율 입력_01.범위명'!J55:J64,">0") -> 10 | G23: =COUNTIF('진행율 입력_01.범위명'!J66:J75,">0") -> 10 | H23: =COUNTIF('진행율 입력_01.범위명'!J77:J86,">0") -> 10 | I23: =COUNTIF('진행율 입력_01.범위명'!J88:J97,">0") -> 10 | J23: =SUM(B23:I23) -> 80
A24: 진행중인 태스크 수 | B24: =COUNTIF('진행율 입력_01.범위명'!O11:O20,"진행") -> 0 | C24: =COUNTIF('진행율 입력_01.범위명'!O22:O31,"진행") -> 0 | D24: =COUNTIF('진행율 입력_01.범위명'!O33:O42,"진행") -> 0 | E24: =COUNTIF('진행율 입력_01.범위명'!O44:O53,"진행") -> 0 | F24: =COUNTIF('진행율 입력_01.범위명'!O55:O64,"진행") -> 0 | G24: =COUNTIF('진행율 입력_01.범위명'!O66:O75,"진행") -> 0 | H24: =COUNTIF('진행율 입력_01.범위명'!O77:O86,"진행") -> 0 | I24: =COUNTIF('진행율 입력_01.범위명'!O88:O97,"진행") -> 0 | J24: =SUM(B24:I24) -> 0
A25: 종료된 태스크 수 | B25: =COUNTIF('진행율 입력_01.범위명'!O11:O20,"종료") -> 2 | C25: =COUNTIF('진행율 입력_01.범위명'!O22:O31,"종료") -> 0 | D25: =COUNTIF('진행율 입력_01.범위명'!O33:O42,"종료") -> 0 | E25: =COUNTIF('진행율 입력_01.범위명'!O44:O53,"종료") -> 0 | F25: =COUNTIF('진행율 입력_01.범위명'!O55:O64,"종료") -> 0 | G25: =COUNTIF('진행율 입력_01.범위명'!O66:O75,"종료") -> 0 | H25: =COUNTIF('진행율 입력_01.범위명'!O77:O86,"종료") -> 0 | I25: =COUNTIF('진행율 입력_01.범위명'!O88:O97,"종료") -> 0 | J25: =SUM(B25:I25) -> 2
A26: 지연된 태스크 수 | B26: =COUNTIF('진행율 입력_01.범위명'!O11:O20,"지연") -> 8 | C26: =COUNTIF('진행율 입력_01.범위명'!O22:O31,"지연") -> 10 | D26: =COUNTIF('진행율 입력_01.범위명'!O33:O42,"지연") -> 10 | E26: =COUNTIF('진행율 입력_01.범위명'!O44:O53,"지연") -> 10 | F26: =COUNTIF('진행율 입력_01.범위명'!O55:O64,"지연") -> 10 | G26: =COUNTIF('진행율 입력_01.범위명'!O66:O75,"지연") -> 10 | H26: =COUNTIF('진행율 입력_01.범위명'!O77:O86,"지연") -> 10 | I26: =COUNTIF('진행율 입력_01.범위명'!O88:O97,"지연") -> 10 | J26: =SUM(B26:I26) -> 78
A27: 계획된 Review 문서 | B27: 0 | C27: 0 | D27: 0 | E27: 0 | F27: 0 | G27: 0 | H27: 0 | I27: 0 | J27: =SUM(B27:I27) -> 0
A28: 완료된 Review 문서 | B28: 0 | C28: 0 | D28: 0 | E28: 0 | F28: 0 | G28: 0 | H28: 0 | I28: 0 | J28: =SUM(B28:I28) -> 0
A29: 각 단계 Review율 | B29: =IF(B27=0, 0, B28/B27) -> 0 | C29: =IF(C27=0, 0, C28/C27) -> 0 | D29: =IF(D27=0, 0, D28/D27) -> 0 | E29: =IF(E27=0, 0, E28/E27) -> 0 | F29: =IF(F27=0, 0, F28/F27) -> 0 | G29: =IF(G27=0, 0, G28/G27) -> 0 | H29: =IF(H27=0, 0, H28/H27) -> 0 | I29: =IF(I27=0, 0, I28/I27) -> 0 | J29: =IF(J27=0, 0, J28/J27) -> 0
A32: 4. 각 단계별 상세 진행 현황 그래프

Sheet 진행율 입력_01.범위명
A1: =표지!C13 -> 사업명 입력 | Y1: =표지!B7 -> 일정관리 및 통제표 (2025년) | CI1: =표지!B7 -> 일정관리 및 통제표 (2025년)
A3: 범위명 | C3: (범위명)
A5: No | B5: 프로세스 | C5: 액티비티 | D5: 태스크 | E5: 세부 태스크-1 | F5: 세부 태스크-2 | G5: 결과물 | H5: 담당자 | I5: 가중치 | J5: 계획 진척 | K5: 실제 진척 | L5: 가중치 계획 | M5: 가중치 실적 | N5: 편차 | O5: 진행 상태 | P5: 계획시작일 | Q5: 계획종료일 | R5: 계획공수 | S5: 실제시작일 | T5: 실제종료일 | U5: 실제공수 | V5: 선행 태스크No | W5: 일정 준수 여부 | X5: CP | Y5: 계획 작업기간 | Z5: 실제 작업기간 | AA5: 01월 | AF5: 02월 | AJ5: 03월 | AN5: 04월 | AS5: 05월 | AW5: 06월 | BA5: 07월 | BF5: 08월 | BJ5: 09월 | BN5: 10월 | BS5: 11월 | BW5: 12월 | CB5: 2026년 1월 | CF5: 2026년 2월
AA6: 1W | AB6: 2W | AC6: 3W | AD6: 4W | AE6: 5W | AF6: 6W | AG6: 7W | AH6: 8W | AI6: 9W | AJ6: 10W | AK6: 11W | AL6: 12W | AM6: 13W | AN6: 14W | AO6: 15W | AP6: 16W | AQ6: 17W | AR6: 18W | AS6: 19W | AT6: 20W | AU6: 21W | AV6: 22W | AW6: 23W | AX6: 24W | AY6: 25W | AZ6: 26W | BA6: 27W | BB6: 28W | BC6: 29W | BD6: 30W | BE6: 31W | BF6: 32W | BG6: 33W | BH6: 34W | BI6: 35W | BJ6: 36W | BK6: 37W | BL6: 38W | BM6: 39W | BN6: 40W | BO6: 41W | BP6: 42W | BQ6: 43W | BR6: 44W | BS6: 45W | BT6: 46W | BU6: 47W | BV6: 48W | BW6: 49W | BX6: 50W | BY6: 51W | BZ6: 52W | CA6: 53W | CB6: 54W | CC6: 55W | CD6: 56W | CE6: 57W | CF6: 58W | CG6: 59W | CH6: 60W | CI6: 61W
AA7: 45656 | AB7: =AA7+7 -> 45663 | AC7: =AB7+7 -> 45670 | AD7: =AC7+7 -> 45677 | AE7: =AD7+7 -> 45684 | AF7: =AE7+7 -> 45691 | AG7: =AF7+7 -> 45698 | AH7: =AG7+7 -> 45705 | AI7: =AH7+7 -> 45712 | ... CI7: =CH7+7 -> 46076
AA8: =AA7+4 -> 45660 | AB8: =AB7+4 -> 45667 | AC8: =AC7+4 -> 45674 | AD8: =AD7+4 -> 45681 | AE8: =AE7+4 -> 45688 | AF8: =AF7+4 -> 45695 | AG8: =AG7+4 -> 45702 | AH8: =AH7+4 -> 45709 | ... CI8: =CI7+4 -> 46080
A9: 0 | I9: =SUM(I10,I21,I32,I43,I65,I54,I76,I87) -> 100 | P9: =MIN(P10,P21,P32,P43,P54,P65,P76,P87) -> 0 | Q9: =MAX(Q10,Q21,Q32,Q43,Q54,Q65,Q76,Q87) -> 45730 | X9: =IF(ISBLANK(V9),"",(DAYS360(VLOOKUP(V9,$A$9:$Q$97,15,FALSE),P9)-1)) | Y9: =NETWORKDAYS(P9,Q9,진행현황_전체!C$59:C$77) -> 32660
A10: 1 | B10: =진행현황_01.범위명!B15 -> 단계1 | H10: =SUM(I11:I20) -> 100 | I10: =진행현황_01.범위명!B16 -> 15 | J10: =SUM(L11:L20) -> 1 | K10: =SUM(M11:M20) -> 0.125 | L10: =SUM(L11:L20)*I10 -> 15 | M10: =SUM(M11:M20)*I10 -> 1.875 | N10: =M10-L10 -> -13.125 | P10: =MIN(P11:P20) -> 45726 | Q10: =MAX(Q11:Q20) -> 45730 | S10: =MIN(S11:S20) -> 45659 | T10: =MAX(T11:T20) -> 45669 | W10: 0.5 | X10: =IF(ISBLANK(V10),"",(DAYS360(VLOOKUP(V10,$A$9:$Q$97,15,FALSE),P10)-1)) | Y10: =NETWORKDAYS(P10,Q10,진행현황_전체!C$59:C$77) -> 5
A11: 1.1 | I11: 2 | J11: =IF(CheckDay>=Q11,1,IF(CheckDay<P11, 0,DAYS360(P11,CheckDay+1)/Y11)) -> 1 | K11: 1 | L11: =I11*J11/100 -> 0.02 | M11: =I11*K11/100 -> 0.02 | N11: =M11-L11 -> 0 | O11: =IF(AND(K11=0%,N11=0),"",IF(N11<0,"지연",IF(K11=100%,"종료","진행"))) -> 종료 | P11: 45726 | Q11: 45730 | S11: 45659 | T11: 45662 | W11: O | X11: =IF(ISBLANK(V11),"",(DAYS360(VLOOKUP(V11,$A$9:$Q$97,15,FALSE),P11)-1)) | Y11: =NETWORKDAYS(P11,Q11,진행현황_전체!C$59:C$77) -> 5 | AA11: =IF(OR((AND($P11<=AA$7,AND($Q11<=AA$8, $Q11>=AA$7))),(AND(AND($P11>=AA$7, $P11<=AA$8),$Q11>=AA$8)), AND($P11>=AA$7, $Q11<=AA$8), AND($P11<=AA$7,$Q11>=AA$8)),1,0) -> 0 | AB11: =IF(OR((AND($P11<=AB$7,AND($Q11<=AB$8, $Q11>=AB$7))),(AND(AND($P11>=AB$7, $P11<=AB$8),$Q11>=AB$8)), AND($P11>=AB$7, $Q11<=AB$8), AND($P11<=AB$7,$Q11>=AB$8)),1,0) -> 0 | AC11: =IF(OR((AND($P11<=AC$7,AND($Q11<=AC$8, $Q11>=AC$7))),(AND(AND($P11>=AC$7, $P11<=AC$8),$Q11>=AC$8)), AND($P11>=AC$7, $Q11<=AC$8), AND($P11<=AC$7,$Q11>=AC$8)),1,0) -> 0 | AD11: =IF(OR((AND($P11<=AD$7,AND($Q11<=AD$8, $Q11>=AD$7))),(AND(AND($P11>=AD$7, $P11<=AD$8),$Q11>=AD$8)), AND($P11>=AD$7, $Q11<=AD$8), AND($P11<=AD$7,$Q11>=AD$8)),1,0) -> 0 | AE11: =IF(OR((AND($P11<=AE$7,AND($Q11<=AE$8, $Q11>=AE$7))),(AND(AND($P11>=AE$7, $P11<=AE$8),$Q11>=AE$8)), AND($P11>=AE$7, $Q11<=AE$8), AND($P11<=AE$7,$Q11>=AE$8)),1,0) -> 0 | AF11: =IF(OR((AND($P11<=AF$7,AND($Q11<=AF$8, $Q11>=AF$7))),(AND(AND($P11>=AF$7, $P11<=AF$8),$Q11>=AF$8)), AND($P11>=AF$7, $Q11<=AF$8), AND($P11<=AF$7,$Q11>=AF$8)),1,0) -> 0 | AG11: =IF(OR((AND($P11<=AG$7,AND($Q11<=AG$8, $Q11>=AG$7))),(AND(AND($P11>=AG$7, $P11<=AG$8),$Q11>=AG$8)), AND($P11>=AG$7, $Q11<=AG$8), AND($P11<=AG$7,$Q11>=AG$8)),1,0) -> 0 | AH11: =IF(OR((AND($P11<=AH$7,AND($Q11<=AH$8, $Q11>=AH$7))),(AND(AND($P11>=AH$7, $P11<=AH$8),$Q11>=AH$8)), AND($P11>=AH$7, $Q11<=AH$8), AND($P11<=AH$7,$Q11>=AH$8)),1,0) -> 0 | ... CI11: =IF(OR((AND($P11<=CI$7,AND($Q11<=CI$8, $Q11>=CI$7))),(AND(AND($P11>=CI$7, $P11<=CI$8),$Q11>=CI$8)), AND($P11>=CI$7, $Q11<=CI$8), AND($P11<=CI$7,$Q11>=CI$8)),1,0) -> 0
A12: 1.2 | I12: 10 | J12: =IF(CheckDay>=Q12,1,IF(CheckDay<P12, 0,DAYS360(P12,CheckDay+1)/Y12)) -> 1 | K12: 1 | L12: =I12*J12/100 -> 0.1 | M12: =I12*K12/100 -> 0.1 | N12: =M12-L12 -> 0 | O12: =IF(AND(K12=0%,N12=0),"",IF(N12<0,"지연",IF(K12=100%,"종료","진행"))) -> 종료 | P12: 45726 | Q12: 45730 | S12: 45667 | T12: 45669 | W12: X | X12: =IF(ISBLANK(V12),"",(DAYS360(VLOOKUP(V12,$A$9:$Q$97,15,FALSE),P12)-1)) | Y12: =NETWORKDAYS(P12,Q12,진행현황_전체!C$59:C$77) -> 5 | AA12: =IF(OR((AND($P12<=AA$7,AND($Q12<=AA$8, $Q12>=AA$7))),(AND(AND($P12>=AA$7, $P12<=AA$8),$Q12>=AA$8)), AND($P12>=AA$7, $Q12<=AA$8), AND($P12<=AA$7,$Q12>=AA$8)),1,0) -> 0 | AB12: =IF(OR((AND($P12<=AB$7,AND($Q12<=AB$8, $Q12>=AB$7))),(AND(AND($P12>=AB$7, $P12<=AB$8),$Q12>=AB$8)), AND($P12>=AB$7, $Q12<=AB$8), AND($P12<=AB$7,$Q12>=AB$8)),1,0) -> 0 | AC12: =IF(OR((AND($P12<=AC$7,AND($Q12<=AC$8, $Q12>=AC$7))),(AND(AND($P12>=AC$7, $P12<=AC$8),$Q12>=AC$8)), AND($P12>=AC$7, $Q12<=AC$8), AND($P12<=AC$7,$Q12>=AC$8)),1,0) -> 0 | AD12: =IF(OR((AND($P12<=AD$7,AND($Q12<=AD$8, $Q12>=AD$7))),(AND(AND($P12>=AD$7, $P12<=AD$8),$Q12>=AD$8)), AND($P12>=AD$7, $Q12<=AD$8), AND($P12<=AD$7,$Q12>=AD$8)),1,0) -> 0 | AE12: =IF(OR((AND($P12<=AE$7,AND($Q12<=AE$8, $Q12>=AE$7))),(AND(AND($P12>=AE$7, $P12<=AE$8),$Q12>=AE$8)), AND($P12>=AE$7, $Q12<=AE$8), AND($P12<=AE$7,$Q12>=AE$8)),1,0) -> 0 | AF12: =IF(OR((AND($P12<=AF$7,AND($Q12<=AF$8, $Q12>=AF$7))),(AND(AND($P12>=AF$7, $P12<=AF$8),$Q12>=AF$8)), AND($P12>=AF$7, $Q12<=AF$8), AND($P12<=AF$7,$Q12>=AF$8)),1,0) -> 0 | AG12: =IF(OR((AND($P12<=AG$7,AND($Q12<=AG$8, $Q12>=AG$7))),(AND(AND($P12>=AG$7, $P12<=AG$8),$Q12>=AG$8)), AND($P12>=AG$7, $Q12<=AG$8), AND($P12<=AG$7,$Q12>=AG$8)),1,0) -> 0 | AH12: =IF(OR((AND($P12<=AH$7,AND($Q12<=AH$8, $Q12>=AH$7))),(AND(AND($P12>=AH$7, $P12<=AH$8),$Q12>=AH$8)), AND($P12>=AH$7, $Q12<=AH$8), AND($P12<=AH$7,$Q12>=AH$8)),1,0) -> 0 | ... CI12: =IF(OR((AND($P12<=CI$7,AND($Q12<=CI$8, $Q12>=CI$7))),(AND(AND($P12>=CI$7, $P12<=CI$8),$Q12>=CI$8)), AND($P12>=CI$7, $Q12<=CI$8), AND($P12<=CI$7,$Q12>=CI$8)),1,0) -> 0
A13: 1.3 | I13: 5 | J13: =IF(CheckDay>=Q13,1,IF(CheckDay<P13, 0,DAYS360(P13,CheckDay+1)/Y13)) -> 1 | K13: 0.1 | L13: =I13*J13/100 -> 0.05 | M13: =I13*K13/100 -> 0.005 | N13: =M13-L13 -> -0.045 | O13: =IF(AND(K13=0%,N13=0),"",IF(N13<0,"지연",IF(K13=100%,"종료","진행"))) -> 지연 | W13: O | X13: =IF(ISBLANK(V13),"",(DAYS360(VLOOKUP(V13,$A$9:$Q$97,15,FALSE),P13)-1)) | Y13: =NETWORKDAYS(P13,Q13,진행현황_전체!C$59:C$77) -> 0 | AA13: =IF(OR((AND($P13<=AA$7,AND($Q13<=AA$8, $Q13>=AA$7))),(AND(AND($P13>=AA$7, $P13<=AA$8),$Q13>=AA$8)), AND($P13>=AA$7, $Q13<=AA$8), AND($P13<=AA$7,$Q13>=AA$8)),1,0) -> 0 | AB13: =IF(OR((AND($P13<=AB$7,AND($Q13<=AB$8, $Q13>=AB$7))),(AND(AND($P13>=AB$7, $P13<=AB$8),$Q13>=AB$8)), AND($P13>=AB$7, $Q13<=AB$8), AND($P13<=AB$7,$Q13>=AB$8)),1,0) -> 0 | AC13: =IF(OR((AND($P13<=AC$7,AND($Q13<=AC$8, $Q13>=AC$7))),(AND(AND($P13>=AC$7, $P13<=AC$8),$Q13>=AC$8)), AND($P13>=AC$7, $Q13<=AC$8), AND($P13<=AC$7,$Q13>=AC$8)),1,0) -> 0 | AD13: =IF(OR((AND($P13<=AD$7,AND($Q13<=AD$8, $Q13>=AD$7))),(AND(AND($P13>=AD$7, $P13<=AD$8),$Q13>=AD$8)), AND($P13>=AD$7, $Q13<=AD$8), AND($P13<=AD$7,$Q13>=AD$8)),1,0) -> 0 | AE13: =IF(OR((AND($P13<=AE$7,AND($Q13<=AE$8, $Q13>=AE$7))),(AND(AND($P13>=AE$7, $P13<=AE$8),$Q13>=AE$8)), AND($P13>=AE$7, $Q13<=AE$8), AND($P13<=AE$7,$Q13>=AE$8)),1,0) -> 0 | AF13: =IF(OR((AND($P13<=AF$7,AND($Q13<=AF$8, $Q13>=AF$7))),(AND(AND($P13>=AF$7, $P13<=AF$8),$Q13>=AF$8)), AND($P13>=AF$7, $Q13<=AF$8), AND($P13<=AF$7,$Q13>=AF$8)),1,0) -> 0 | AG13: =IF(OR((AND($P13<=AG$7,AND($Q13<=AG$8, $Q13>=AG$7))),(AND(AND($P13>=AG$7, $P13<=AG$8),$Q13>=AG$8)), AND($P13>=AG$7, $Q13<=AG$8), AND($P13<=AG$7,$Q13>=AG$8)),1,0) -> 0 | AH13: =IF(OR((AND($P13<=AH$7,AND($Q13<=AH$8, $Q13>=AH$7))),(AND(AND($P13>=AH$7, $P13<=AH$8),$Q13>=AH$8)), AND($P13>=AH$7, $Q13<=AH$8), AND($P13<=AH$7,$Q13>=AH$8)),1,0) -> 0 | ... CI13: =IF(OR((AND($P13<=CI$7,AND($Q13<=CI$8, $Q13>=CI$7))),(AND(AND($P13>=CI$7, $P13<=CI$8),$Q13>=CI$8)), AND($P13>=CI$7, $Q13<=CI$8), AND($P13<=CI$7,$Q13>=CI$8)),1,0) -> 0
A14: 1.4 | I14: 10 | J14: =IF(CheckDay>=Q14,1,IF(CheckDay<P14, 0,DAYS360(P14,CheckDay+1)/Y14)) -> 1 | K14: 0 | L14: =I14*J14/100 -> 0.1 | M14: =I14*K14/100 -> 0 | N14: =M14-L14 -> -0.1 | O14: =IF(AND(K14=0%,N14=0),"",IF(N14<0,"지연",IF(K14=100%,"종료","진행"))) -> 지연 | W14: X | X14: =IF(ISBLANK(V14),"",(DAYS360(VLOOKUP(V14,$A$9:$Q$97,15,FALSE),P14)-1)) | Y14: =NETWORKDAYS(P14,Q14,진행현황_전체!C$59:C$77) -> 0 | AA14: =IF(OR((AND($P14<=AA$7,AND($Q14<=AA$8, $Q14>=AA$7))),(AND(AND($P14>=AA$7, $P14<=AA$8),$Q14>=AA$8)), AND($P14>=AA$7, $Q14<=AA$8), AND($P14<=AA$7,$Q14>=AA$8)),1,0) -> 0 | AB14: =IF(OR((AND($P14<=AB$7,AND($Q14<=AB$8, $Q14>=AB$7))),(AND(AND($P14>=AB$7, $P14<=AB$8),$Q14>=AB$8)), AND($P14>=AB$7, $Q14<=AB$8), AND($P14<=AB$7,$Q14>=AB$8)),1,0) -> 0 | AC14: =IF(OR((AND($P14<=AC$7,AND($Q14<=AC$8, $Q14>=AC$7))),(AND(AND($P14>=AC$7, $P14<=AC$8),$Q14>=AC$8)), AND($P14>=AC$7, $Q14<=AC$8), AND($P14<=AC$7,$Q14>=AC$8)),1,0) -> 0 | AD14: =IF(OR((AND($P14<=AD$7,AND($Q14<=AD$8, $Q14>=AD$7))),(AND(AND($P14>=AD$7, $P14<=AD$8),$Q14>=AD$8)), AND($P14>=AD$7, $Q14<=AD$8), AND($P14<=AD$7,$Q14>=AD$8)),1,0) -> 0 | AE14: =IF(OR((AND($P14<=AE$7,AND($Q14<=AE$8, $Q14>=AE$7))),(AND(AND($P14>=AE$7, $P14<=AE$8),$Q14>=AE$8)), AND($P14>=AE$7, $Q14<=AE$8), AND($P14<=AE$7,$Q14>=AE$8)),1,0) -> 0 | AF14: =IF(OR((AND($P14<=AF$7,AND($Q14<=AF$8, $Q14>=AF$7))),(AND(AND($P14>=AF$7, $P14<=AF$8),$Q14>=AF$8)), AND($P14>=AF$7, $Q14<=AF$8), AND($P14<=AF$7,$Q14>=AF$8)),1,0) -> 0 | AG14: =IF(OR((AND($P14<=AG$7,AND($Q14<=AG$8, $Q14>=AG$7))),(AND(AND($P14>=AG$7, $P14<=AG$8),$Q14>=AG$8)), AND($P14>=AG$7, $Q14<=AG$8), AND($P14<=AG$7,$Q14>=AG$8)),1,0) -> 0 | AH14: =IF(OR((AND($P14<=AH$7,AND($Q14<=AH$8, $Q14>=AH$7))),(AND(AND($P14>=AH$7, $P14<=AH$8),$Q14>=AH$8)), AND($P14>=AH$7, $Q14<=AH$8), AND($P14<=AH$7,$Q14>=AH$8)),1,0) -> 0 | ... CI14: =IF(OR((AND($P14<=CI$7,AND($Q14<=CI$8, $Q14>=CI$7))),(AND(AND($P14>=CI$7, $P14<=CI$8),$Q14>=CI$8)), AND($P14>=CI$7, $Q14<=CI$8), AND($P14<=CI$7,$Q14>=CI$8)),1,0) -> 0
A15: 1.5 | I15: 10 | J15: =IF(CheckDay>=Q15,1,IF(CheckDay<P15, 0,DAYS360(P15,CheckDay+1)/Y15)) -> 1 | K15: 0 | L15: =I15*J15/100 -> 0.1 | M15: =I15*K15/100 -> 0 | N15: =M15-L15 -> -0.1 | O15: =IF(AND(K15=0%,N15=0),"",IF(N15<0,"지연",IF(K15=100%,"종료","진행"))) -> 지연 | W15: O | X15: =IF(ISBLANK(V15),"",(DAYS360(VLOOKUP(V15,$A$9:$Q$97,15,FALSE),P15)-1)) | Y15: =NETWORKDAYS(P15,Q15,진행현황_전체!C$59:C$77) -> 0 | AA15: =IF(OR((AND($P15<=AA$7,AND($Q15<=AA$8, $Q15>=AA$7))),(AND(AND($P15>=AA$7, $P15<=AA$8),$Q15>=AA$8)), AND($P15>=AA$7, $Q15<=AA$8), AND($P15<=AA$7,$Q15>=AA$8)),1,0) -> 0 | AB15: =IF(OR((AND($P15<=AB$7,AND($Q15<=AB$8, $Q15>=AB$7))),(AND(AND($P15>=AB$7, $P15<=AB$8),$Q15>=AB$8)), AND($P15>=AB$7, $Q15<=AB$8), AND($P15<=AB$7,$Q15>=AB$8)),1,0) -> 0 | AC15: =IF(OR((AND($P15<=AC$7,AND($Q15<=AC$8, $Q15>=AC$7))),(AND(AND($P15>=AC$7, $P15<=AC$8),$Q15>=AC$8)), AND($P15>=AC$7, $Q15<=AC$8), AND($P15<=AC$7,$Q15>=AC$8)),1,0) -> 0 | AD15: =IF(OR((AND($P15<=AD$7,AND($Q15<=AD$8, $Q15>=AD$7))),(AND(AND($P15>=AD$7, $P15<=AD$8),$Q15>=AD$8)), AND($P15>=AD$7, $Q15<=AD$8), AND($P15<=AD$7,$Q15>=AD$8)),1,0) -> 0 | AE15: =IF(OR((AND($P15<=AE$7,AND($Q15<=AE$8, $Q15>=AE$7))),(AND(AND($P15>=AE$7, $P15<=AE$8),$Q15>=AE$8)), AND($P15>=AE$7, $Q15<=AE$8), AND($P15<=AE$7,$Q15>=AE$8)),1,0) -> 0 | AF15: =IF(OR((AND($P15<=AF$7,AND($Q15<=AF$8, $Q15>=AF$7))),(AND(AND($P15>=AF$7, $P15<=AF$8),$Q15>=AF$8)), AND($P15>=AF$7, $Q15<=AF$8), AND($P15<=AF$7,$Q15>=AF$8)),1,0) -> 0 | AG15: =IF(OR((AND($P15<=AG$7,AND($Q15<=AG$8, $Q15>=AG$7))),(AND(AND($P15>=AG$7, $P15<=AG$8),$Q15>=AG$8)), AND($P15>=AG$7, $Q15<=AG$8), AND($P15<=AG$7,$Q15>=AG$8)),1,0) -> 0 | AH15: =IF(OR((AND($P15<=AH$7,AND($Q15<=AH$8, $Q15>=AH$7))),(AND(AND($P15>=AH$7, $P15<=AH$8),$Q15>=AH$8)), AND($P15>=AH$7, $Q15<=AH$8), AND($P15<=AH$7,$Q15>=AH$8)),1,0) -> 0 | ... CI15: =IF(OR((AND($P15<=CI$7,AND($Q15<=CI$8, $Q15>=CI$7))),(AND(AND($P15>=CI$7, $P15<=CI$8),$Q15>=CI$8)), AND($P15>=CI$7, $Q15<=CI$8), AND($P15<=CI$7,$Q15>=CI$8)),1,0) -> 0
A16: 1.6 | I16: 18 | J16: =IF(CheckDay>=Q16,1,IF(CheckDay<P16, 0,DAYS360(P16,CheckDay+1)/Y16)) -> 1 | K16: 0 | L16: =I16*J16/100 -> 0.18 | M16: =I16*K16/100 -> 0 | N16: =M16-L16 -> -0.18 | O16: =IF(AND(K16=0%,N16=0),"",IF(N16<0,"지연",IF(K16=100%,"종료","진행"))) -> 지연 | W16: X | X16: =IF(ISBLANK(V16),"",(DAYS360(VLOOKUP(V16,$A$9:$Q$97,15,FALSE),P16)-1)) | Y16: =NETWORKDAYS(P16,Q16,진행현황_전체!C$59:C$77) -> 0 | AA16: =IF(OR((AND($P16<=AA$7,AND($Q16<=AA$8, $Q16>=AA$7))),(AND(AND($P16>=AA$7, $P16<=AA$8),$Q16>=AA$8)), AND($P16>=AA$7, $Q16<=AA$8), AND($P16<=AA$7,$Q16>=AA$8)),1,0) -> 0 | AB16: =IF(OR((AND($P16<=AB$7,AND($Q16<=AB$8, $Q16>=AB$7))),(AND(AND($P16>=AB$7, $P16<=AB$8),$Q16>=AB$8)), AND($P16>=AB$7, $Q16<=AB$8), AND($P16<=AB$7,$Q16>=AB$8)),1,0) -> 0 | AC16: =IF(OR((AND($P16<=AC$7,AND($Q16<=AC$8, $Q16>=AC$7))),(AND(AND($P16>=AC$7, $P16<=AC$8),$Q16>=AC$8)), AND($P16>=AC$7, $Q16<=AC$8), AND($P16<=AC$7,$Q16>=AC$8)),1,0) -> 0 | AD16: =IF(OR((AND($P16<=AD$7,AND($Q16<=AD$8, $Q16>=AD$7))),(AND(AND($P16>=AD$7, $P16<=AD$8),$Q16>=AD$8)), AND($P16>=AD$7, $Q16<=AD$8), AND($P16<=AD$7,$Q16>=AD$8)),1,0) -> 0 | AE16: =IF(OR((AND($P16<=AE$7,AND($Q16<=AE$8, $Q16>=AE$7))),(AND(AND($P16>=AE$7, $P16<=AE$8),$Q16>=AE$8)), AND($P16>=AE$7, $Q16<=AE$8), AND($P16<=AE$7,$Q16>=AE$8)),1,0) -> 0 | AF16: =IF(OR((AND($P16<=AF$7,AND($Q16<=AF$8, $Q16>=AF$7))),(AND(AND($P16>=AF$7, $P16<=AF$8),$Q16>=AF$8)), AND($P16>=AF$7, $Q16<=AF$8), AND($P16<=AF$7,$Q16>=AF$8)),1,0) -> 0 | AG16: =IF(OR((AND($P16<=AG$7,AND($Q16<=AG$8, $Q16>=AG$7))),(AND(AND($P16>=AG$7, $P16<=AG$8),$Q16>=AG$8)), AND($P16>=AG$7, $Q16<=AG$8), AND($P16<=AG$7,$Q16>=AG$8)),1,0) -> 0 | AH16: =IF(OR((AND($P16<=AH$7,AND($Q16<=AH$8, $Q16>=AH$7))),(AND(AND($P16>=AH$7, $P16<=AH$8),$Q16>=AH$8)), AND($P16>=AH$7, $Q16<=AH$8), AND($P16<=AH$7,$Q16>=AH$8)),1,0) -> 0 | ... CI16: =IF(OR((AND($P16<=CI$7,AND($Q16<=CI$8, $Q16>=CI$7))),(AND(AND($P16>=CI$7, $P16<=CI$8),$Q16>=CI$8)), AND($P16>=CI$7, $Q16<=CI$8), AND($P16<=CI$7,$Q16>=CI$8)),1,0) -> 0
A17: 1.7 | I17: 10 | J17: =IF(CheckDay>=Q17,1,IF(CheckDay<P17, 0,DAYS360(P17,CheckDay+1)/Y17)) -> 1 | K17: 0 | L17: =I17*J17/100 -> 0.1 | M17: =I17*K17/100 -> 0 | N17: =M17-L17 -> -0.1 | O17: =IF(AND(K17=0%,N17=0),"",IF(N17<0,"지연",IF(K17=100%,"종료","진행"))) -> 지연 | W17: O | X17: =IF(ISBLANK(V17),"",(DAYS360(VLOOKUP(V17,$A$9:$Q$97,15,FALSE),P17)-1)) | Y17: =NETWORKDAYS(P17,Q17,진행현황_전체!C$59:C$77) -> 0 | AA17: =IF(OR((AND($P17<=AA$7,AND($Q17<=AA$8, $Q17>=AA$7))),(AND(AND($P17>=AA$7, $P17<=AA$8),$Q17>=AA$8)), AND($P17>=AA$7, $Q17<=AA$8), AND($P17<=AA$7,$Q17>=AA$8)),1,0) -> 0 | AB17: =IF(OR((AND($P17<=AB$7,AND($Q17<=AB$8, $Q17>=AB$7))),(AND(AND($P17>=AB$7, $P17<=AB$8),$Q17>=AB$8)), AND($P17>=AB$7, $Q17<=AB$8), AND($P17<=AB$7,$Q17>=AB$8)),1,0) -> 0 | AC17: =IF(OR((AND($P17<=AC$7,AND($Q17<=AC$8, $Q17>=AC$7))),(AND(AND($P17>=AC$7, $P17<=AC$8),$Q17>=AC$8)), AND($P17>=AC$7, $Q17<=AC$8), AND($P17<=AC$7,$Q17>=AC$8)),1,0) -> 0 | AD17: =IF(OR((AND($P17<=AD$7,AND($Q17<=AD$8, $Q17>=AD$7))),(AND(AND($P17>=AD$7, $P17<=AD$8),$Q17>=AD$8)), AND($P17>=AD$7, $Q17<=AD$8), AND($P17<=AD$7,$Q17>=AD$8)),1,0) -> 0 | AE17: =IF(OR((AND($P17<=AE$7,AND($Q17<=AE$8, $Q17>=AE$7))),(AND(AND($P17>=AE$7, $P17<=AE$8),$Q17>=AE$8)), AND($P17>=AE$7, $Q17<=AE$8), AND($P17<=AE$7,$Q17>=AE$8)),1,0) -> 0 | AF17: =IF(OR((AND($P17<=AF$7,AND($Q17<=AF$8, $Q17>=AF$7))),(AND(AND($P17>=AF$7, $P17<=AF$8),$Q17>=AF$8)), AND($P17>=AF$7, $Q17<=AF$8), AND($P17<=AF$7,$Q17>=AF$8)),1,0) -> 0 | AG17: =IF(OR((AND($P17<=AG$7,AND($Q17<=AG$8, $Q17>=AG$7))),(AND(AND($P17>=AG$7, $P17<=AG$8),$Q17>=AG$8)), AND($P17>=AG$7, $Q17<=AG$8), AND($P17<=AG$7,$Q17>=AG$8)),1,0) -> 0 | AH17: =IF(OR((AND($P17<=AH$7,AND($Q17<=AH$8, $Q17>=AH$7))),(AND(AND($P17>=AH$7, $P17<=AH$8),$Q17>=AH$8)), AND($P17>=AH$7, $Q17<=AH$8), AND($P17<=AH$7,$Q17>=AH$8)),1,0) -> 0 | ... CI17: =IF(OR((AND($P17<=CI$7,AND($Q17<=CI$8, $Q17>=CI$7))),(AND(AND($P17>=CI$7, $P17<=CI$8),$Q17>=CI$8)), AND($P17>=CI$7, $Q17<=CI$8), AND($P17<=CI$7,$Q17>=CI$8)),1,0) -> 0
A18: 1.8 | I18: 15 | J18: =IF(CheckDay>=Q18,1,IF(CheckDay<P18, 0,DAYS360(P18,CheckDay+1)/Y18)) -> 1 | K18: 0 | L18: =I18*J18/100 -> 0.15 | M18: =I18*K18/100 -> 0 | N18: =M18-L18 -> -0.15 | O18: =IF(AND(K18=0%,N18=0),"",IF(N18<0,"지연",IF(K18=100%,"종료","진행"))) -> 지연 | W18: X | X18: =IF(ISBLANK(V18),"",(DAYS360(VLOOKUP(V18,$A$9:$Q$97,15,FALSE),P18)-1)) | Y18: =NETWORKDAYS(P18,Q18,진행현황_전체!C$59:C$77) -> 0 | AA18: =IF(OR((AND($P18<=AA$7,AND($Q18<=AA$8, $Q18>=AA$7))),(AND(AND($P18>=AA$7, $P18<=AA$8),$Q18>=AA$8)), AND($P18>=AA$7, $Q18<=AA$8), AND($P18<=AA$7,$Q18>=AA$8)),1,0) -> 0 | AB18: =IF(OR((AND($P18<=AB$7,AND($Q18<=AB$8, $Q18>=AB$7))),(AND(AND($P18>=AB$7, $P18<=AB$8),$Q18>=AB$8)), AND($P18>=AB$7, $Q18<=AB$8), AND($P18<=AB$7,$Q18>=AB$8)),1,0) -> 0 | AC18: =IF(OR((AND($P18<=AC$7,AND($Q18<=AC$8, $Q18>=AC$7))),(AND(AND($P18>=AC$7, $P18<=AC$8),$Q18>=AC$8)), AND($P18>=AC$7, $Q18<=AC$8), AND($P18<=AC$7,$Q18>=AC$8)),1,0) -> 0 | AD18: =IF(OR((AND($P18<=AD$7,AND($Q18<=AD$8, $Q18>=AD$7))),(AND(AND($P18>=AD$7, $P18<=AD$8),$Q18>=AD$8)), AND($P18>=AD$7, $Q18<=AD$8), AND($P18<=AD$7,$Q18>=AD$8)),1,0) -> 0 | AE18: =IF(OR((AND($P18<=AE$7,AND($Q18<=AE$8, $Q18>=AE$7))),(AND(AND($P18>=AE$7, $P18<=AE$8),$Q18>=AE$8)), AND($P18>=AE$7, $Q18<=AE$8), AND($P18<=AE$7,$Q18>=AE$8)),1,0) -> 0 | AF18: =IF(OR((AND($P18<=AF$7,AND($Q18<=AF$8, $Q18>=AF$7))),(AND(AND($P18>=AF$7, $P18<=AF$8),$Q18>=AF$8)), AND($P18>=AF$7, $Q18<=AF$8), AND($P18<=AF$7,$Q18>=AF$8)),1,0) -> 0 | AG18: =IF(OR((AND($P18<=AG$7,AND($Q18<=AG$8, $Q18>=AG$7))),(AND(AND($P18>=AG$7, $P18<=AG$8),$Q18>=AG$8)), AND($P18>=AG$7, $Q18<=AG$8), AND($P18<=AG$7,$Q18>=AG$8)),1,0) -> 0 | AH18: =IF(OR((AND($P18<=AH$7,AND($Q18<=AH$8, $Q18>=AH$7))),(AND(AND($P18>=AH$7, $P18<=AH$8),$Q18>=AH$8)), AND($P18>=AH$7, $Q18<=AH$8), AND($P18<=AH$7,$Q18>=AH$8)),1,0) -> 0 | ... CI18: =IF(OR((AND($P18<=CI$7,AND($Q18<=CI$8, $Q18>=CI$7))),(AND(AND($P18>=CI$7, $P18<=CI$8),$Q18>=CI$8)), AND($P18>=CI$7, $Q18<=CI$8), AND($P18<=CI$7,$Q18>=CI$8)),1,0) -> 0
A19: 1.9 | I19: 10 | J19: =IF(CheckDay>=Q19,1,IF(CheckDay<P19, 0,DAYS360(P19,CheckDay+1)/Y19)) -> 1 | K19: 0 | L19: =I19*J19/100 -> 0.1 | M19: =I19*K19/100 -> 0 | N19: =M19-L19 -> -0.1 | O19: =IF(AND(K19=0%,N19=0),"",IF(N19<0,"지연",IF(K19=100%,"종료","진행"))) -> 지연 | W19: O | X19: =IF(ISBLANK(V19),"",(DAYS360(VLOOKUP(V19,$A$9:$Q$97,15,FALSE),P19)-1)) | Y19: =NETWORKDAYS(P19,Q19,진행현황_전체!C$59:C$77) -> 0 | AA19: =IF(OR((AND($P19<=AA$7,AND($Q19<=AA$8, $Q19>=AA$7))),(AND(AND($P19>=AA$7, $P19<=AA$8),$Q19>=AA$8)), AND($P19>=AA$7, $Q19<=AA$8), AND($P19<=AA$7,$Q19>=AA$8)),1,0) -> 0 | AB19: =IF(OR((AND($P19<=AB$7,AND($Q19<=AB$8, $Q19>=AB$7))),(AND(AND($P19>=AB$7, $P19<=AB$8),$Q19>=AB$8)), AND($P19>=AB$7, $Q19<=AB$8), AND($P19<=AB$7,$Q19>=AB$8)),1,0) -> 0 | AC19: =IF(OR((AND($P19<=AC$7,AND($Q19<=AC$8, $Q19>=AC$7))),(AND(AND($P19>=AC$7, $P19<=AC$8),$Q19>=AC$8)), AND($P19>=AC$7, $Q19<=AC$8), AND($P19<=AC$7,$Q19>=AC$8)),1,0) -> 0 | AD19: =IF(OR((AND($P19<=AD$7,AND($Q19<=AD$8, $Q19>=AD$7))),(AND(AND($P19>=AD$7, $P19<=AD$8),$Q19>=AD$8)), AND($P19>=AD$7, $Q19<=AD$8), AND($P19<=AD$7,$Q19>=AD$8)),1,0) -> 0 | AE19: =IF(OR((AND($P19<=AE$7,AND($Q19<=AE$8, $Q19>=AE$7))),(AND(AND($P19>=AE$7, $P19<=AE$8),$Q19>=AE$8)), AND($P19>=AE$7, $Q19<=AE$8), AND($P19<=AE$7,$Q19>=AE$8)),1,0) -> 0 | AF19: =IF(OR((AND($P19<=AF$7,AND($Q19<=AF$8, $Q19>=AF$7))),(AND(AND($P19>=AF$7, $P19<=AF$8),$Q19>=AF$8)), AND($P19>=AF$7, $Q19<=AF$8), AND($P19<=AF$7,$Q19>=AF$8)),1,0) -> 0 | AG19: =IF(OR((AND($P19<=AG$7,AND($Q19<=AG$8, $Q19>=AG$7))),(AND(AND($P19>=AG$7, $P19<=AG$8),$Q19>=AG$8)), AND($P19>=AG$7, $Q19<=AG$8), AND($P19<=AG$7,$Q19>=AG$8)),1,0) -> 0 | AH19: =IF(OR((AND($P19<=AH$7,AND($Q19<=AH$8, $Q19>=AH$7))),(AND(AND($P19>=AH$7, $P19<=AH$8),$Q19>=AH$8)), AND($P19>=AH$7, $Q19<=AH$8), AND($P19<=AH$7,$Q19>=AH$8)),1,0) -> 0 | ... CI19: =IF(OR((AND($P19<=CI$7,AND($Q19<=CI$8, $Q19>=CI$7))),(AND(AND($P19>=CI$7, $P19<=CI$8),$Q19>=CI$8)), AND($P19>=CI$7, $Q19<=CI$8), AND($P19<=CI$7,$Q19>=CI$8)),1,0) -> 0
A20: 1.10 | I20: 10 | J20: =IF(CheckDay>=Q20,1,IF(CheckDay<P20, 0,DAYS360(P20,CheckDay+1)/Y20)) -> 1 | K20: 0 | L20: =I20*J20/100 -> 0.1 | M20: =I20*K20/100 -> 0 | N20: =M20-L20 -> -0.1 | O20: =IF(AND(K20=0%,N20=0),"",IF(N20<0,"지연",IF(K20=100%,"종료","진행"))) -> 지연 | W20: X | X20: =IF(ISBLANK(V20),"",(DAYS360(VLOOKUP(V20,$A$9:$Q$97,15,FALSE),P20)-1)) | Y20: =NETWORKDAYS(P20,Q20,진행현황_전체!C$59:C$77) -> 0 | AA20: =IF(OR((AND($P20<=AA$7,AND($Q20<=AA$8, $Q20>=AA$7))),(AND(AND($P20>=AA$7, $P20<=AA$8),$Q20>=AA$8)), AND($P20>=AA$7, $Q20<=AA$8), AND($P20<=AA$7,$Q20>=AA$8)),1,0) -> 0 | AB20: =IF(OR((AND($P20<=AB$7,AND($Q20<=AB$8, $Q20>=AB$7))),(AND(AND($P20>=AB$7, $P20<=AB$8),$Q20>=AB$8)), AND($P20>=AB$7, $Q20<=AB$8), AND($P20<=AB$7,$Q20>=AB$8)),1,0) -> 0 | AC20: =IF(OR((AND($P20<=AC$7,AND($Q20<=AC$8, $Q20>=AC$7))),(AND(AND($P20>=AC$7, $P20<=AC$8),$Q20>=AC$8)), AND($P20>=AC$7, $Q20<=AC$8), AND($P20<=AC$7,$Q20>=AC$8)),1,0) -> 0 | AD20: =IF(OR((AND($P20<=AD$7,AND($Q20<=AD$8, $Q20>=AD$7))),(AND(AND($P20>=AD$7, $P20<=AD$8),$Q20>=AD$8)), AND($P20>=AD$7, $Q20<=AD$8), AND($P20<=AD$7,$Q20>=AD$8)),1,0) -> 0 | AE20: =IF(OR((AND($P20<=AE$7,AND($Q20<=AE$8, $Q20>=AE$7))),(AND(AND($P20>=AE$7, $P20<=AE$8),$Q20>=AE$8)), AND($P20>=AE$7, $Q20<=AE$8), AND($P20<=AE$7,$Q20>=AE$8)),1,0) -> 0 | AF20: =IF(OR((AND($P20<=AF$7,AND($Q20<=AF$8, $Q20>=AF$7))),(AND(AND($P20>=AF$7, $P20<=AF$8),$Q20>=AF$8)), AND($P20>=AF$7, $Q20<=AF$8), AND($P20<=AF$7,$Q20>=AF$8)),1,0) -> 0 | AG20: =IF(OR((AND($P20<=AG$7,AND($Q20<=AG$8, $Q20>=AG$7))),(AND(AND($P20>=AG$7, $P20<=AG$8),$Q20>=AG$8)), AND($P20>=AG$7, $Q20<=AG$8), AND($P20<=AG$7,$Q20>=AG$8)),1,0) -> 0 | AH20: =IF(OR((AND($P20<=AH$7,AND($Q20<=AH$8, $Q20>=AH$7))),(AND(AND($P20>=AH$7, $P20<=AH$8),$Q20>=AH$8)), AND($P20>=AH$7, $Q20<=AH$8), AND($P20<=AH$7,$Q20>=AH$8)),1,0) -> 0 | ... CI20: =IF(OR((AND($P20<=CI$7,AND($Q20<=CI$8, $Q20>=CI$7))),(AND(AND($P20>=CI$7, $P20<=CI$8),$Q20>=CI$8)), AND($P20>=CI$7, $Q20<=CI$8), AND($P20<=CI$7,$Q20>=CI$8)),1,0) -> 0
A21: 2 | B21: =진행현황_01.범위명!C15 -> 단계2 | H21: =SUM(I22:I31) -> 100 | I21: =진행현황_01.범위명!C16 -> 15 | J21: =SUM(L22:L31) -> 1 | K21: =SUM(M22:M31) -> 0 | L21: =SUM(L22:L31)*I21 -> 15 | M21: =SUM(M22:M31)*I21 -> 0 | N21: =M21-L21 -> -15 | P21: =MIN(P22:P31) -> 0 | Q21: =MAX(Q22:Q31) -> 0 | S21: =MIN(S22:S31) -> 0 | T21: =MAX(T22:T31) -> 0 | X21: =IF(ISBLANK(V21),"",(DAYS360(VLOOKUP(V21,$A$9:$Q$97,15,FALSE),P21)-1)) | Y21: =NETWORKDAYS(P21,Q21,진행현황_전체!C$59:C$77) -> 0
A22: 2.1 | I22: 10 | J22: =IF(CheckDay>=Q22,1,IF(CheckDay<P22, 0,DAYS360(P22,CheckDay+1)/Y22)) -> 1 | K22: 0 | L22: =I22*J22/100 -> 0.1 | M22: =I22*K22/100 -> 0 | N22: =M22-L22 -> -0.1 | O22: =IF(AND(K22=0%,N22=0),"",IF(N22<0,"지연",IF(K22=100%,"종료","진행"))) -> 지연 | X22: =IF(ISBLANK(V22),"",(DAYS360(VLOOKUP(V22,$A$9:$Q$97,15,FALSE),P22)-1)) | Y22: =NETWORKDAYS(P22,Q22,진행현황_전체!C$59:C$77) -> 0 | AA22: =IF(OR((AND($P22<=AA$7,AND($Q22<=AA$8, $Q22>=AA$7))),(AND(AND($P22>=AA$7, $P22<=AA$8),$Q22>=AA$8)), AND($P22>=AA$7, $Q22<=AA$8), AND($P22<=AA$7,$Q22>=AA$8)),1,0) -> 0 | AB22: =IF(OR((AND($P22<=AB$7,AND($Q22<=AB$8, $Q22>=AB$7))),(AND(AND($P22>=AB$7, $P22<=AB$8),$Q22>=AB$8)), AND($P22>=AB$7, $Q22<=AB$8), AND($P22<=AB$7,$Q22>=AB$8)),1,0) -> 0 | AC22: =IF(OR((AND($P22<=AC$7,AND($Q22<=AC$8, $Q22>=AC$7))),(AND(AND($P22>=AC$7, $P22<=AC$8),$Q22>=AC$8)), AND($P22>=AC$7, $Q22<=AC$8), AND($P22<=AC$7,$Q22>=AC$8)),1,0) -> 0 | AD22: =IF(OR((AND($P22<=AD$7,AND($Q22<=AD$8, $Q22>=AD$7))),(AND(AND($P22>=AD$7, $P22<=AD$8),$Q22>=AD$8)), AND($P22>=AD$7, $Q22<=AD$8), AND($P22<=AD$7,$Q22>=AD$8)),1,0) -> 0 | AE22: =IF(OR((AND($P22<=AE$7,AND($Q22<=AE$8, $Q22>=AE$7))),(AND(AND($P22>=AE$7, $P22<=AE$8),$Q22>=AE$8)), AND($P22>=AE$7, $Q22<=AE$8), AND($P22<=AE$7,$Q22>=AE$8)),1,0) -> 0 | AF22: =IF(OR((AND($P22<=AF$7,AND($Q22<=AF$8, $Q22>=AF$7))),(AND(AND($P22>=AF$7, $P22<=AF$8),$Q22>=AF$8)), AND($P22>=AF$7, $Q22<=AF$8), AND($P22<=AF$7,$Q22>=AF$8)),1,0) -> 0 | AG22: =IF(OR((AND($P22<=AG$7,AND($Q22<=AG$8, $Q22>=AG$7))),(AND(AND($P22>=AG$7, $P22<=AG$8),$Q22>=AG$8)), AND($P22>=AG$7, $Q22<=AG$8), AND($P22<=AG$7,$Q22>=AG$8)),1,0) -> 0 | AH22: =IF(OR((AND($P22<=AH$7,AND($Q22<=AH$8, $Q22>=AH$7))),(AND(AND($P22>=AH$7, $P22<=AH$8),$Q22>=AH$8)), AND($P22>=AH$7, $Q22<=AH$8), AND($P22<=AH$7,$Q22>=AH$8)),1,0) -> 0 | ... CI22: =IF(OR((AND($P22<=CI$7,AND($Q22<=CI$8, $Q22>=CI$7))),(AND(AND($P22>=CI$7, $P22<=CI$8),$Q22>=CI$8)), AND($P22>=CI$7, $Q22<=CI$8), AND($P22<=CI$7,$Q22>=CI$8)),1,0) -> 0
A23: 2.2 | I23: 10 | J23: =IF(CheckDay>=Q23,1,IF(CheckDay<P23, 0,DAYS360(P23,CheckDay+1)/Y23)) -> 1 | K23: 0 | L23: =I23*J23/100 -> 0.1 | M23: =I23*K23/100 -> 0 | N23: =M23-L23 -> -0.1 | O23: =IF(AND(K23=0%,N23=0),"",IF(N23<0,"지연",IF(K23=100%,"종료","진행"))) -> 지연 | X23: =IF(ISBLANK(V23),"",(DAYS360(VLOOKUP(V23,$A$9:$Q$97,15,FALSE),P23)-1)) | Y23: =NETWORKDAYS(P23,Q23,진행현황_전체!C$59:C$77) -> 0 | AA23: =IF(OR((AND($P23<=AA$7,AND($Q23<=AA$8, $Q23>=AA$7))),(AND(AND($P23>=AA$7, $P23<=AA$8),$Q23>=AA$8)), AND($P23>=AA$7, $Q23<=AA$8), AND($P23<=AA$7,$Q23>=AA$8)),1,0) -> 0 | AB23: =IF(OR((AND($P23<=AB$7,AND($Q23<=AB$8, $Q23>=AB$7))),(AND(AND($P23>=AB$7, $P23<=AB$8),$Q23>=AB$8)), AND($P23>=AB$7, $Q23<=AB$8), AND($P23<=AB$7,$Q23>=AB$8)),1,0) -> 0 | AC23: =IF(OR((AND($P23<=AC$7,AND($Q23<=AC$8, $Q23>=AC$7))),(AND(AND($P23>=AC$7, $P23<=AC$8),$Q23>=AC$8)), AND($P23>=AC$7, $Q23<=AC$8), AND($P23<=AC$7,$Q23>=AC$8)),1,0) -> 0 | AD23: =IF(OR((AND($P23<=AD$7,AND($Q23<=AD$8, $Q23>=AD$7))),(AND(AND($P23>=AD$7, $P23<=AD$8),$Q23>=AD$8)), AND($P23>=AD$7, $Q23<=AD$8), AND($P23<=AD$7,$Q23>=AD$8)),1,0) -> 0 | AE23: =IF(OR((AND($P23<=AE$7,AND($Q23<=AE$8, $Q23>=AE$7))),(AND(AND($P23>=AE$7, $P23<=AE$8),$Q23>=AE$8)), AND($P23>=AE$7, $Q23<=AE$8), AND($P23<=AE$7,$Q23>=AE$8)),1,0) -> 0 | AF23: =IF(OR((AND($P23<=AF$7,AND($Q23<=AF$8, $Q23>=AF$7))),(AND(AND($P23>=AF$7, $P23<=AF$8),$Q23>=AF$8)), AND($P23>=AF$7, $Q23<=AF$8), AND($P23<=AF$7,$Q23>=AF$8)),1,0) -> 0 | AG23: =IF(OR((AND($P23<=AG$7,AND($Q23<=AG$8, $Q23>=AG$7))),(AND(AND($P23>=AG$7, $P23<=AG$8),$Q23>=AG$8)), AND($P23>=AG$7, $Q23<=AG$8), AND($P23<=AG$7,$Q23>=AG$8)),1,0) -> 0 | AH23: =IF(OR((AND($P23<=AH$7,AND($Q23<=AH$8, $Q23>=AH$7))),(AND(AND($P23>=AH$7, $P23<=AH$8),$Q23>=AH$8)), AND($P23>=AH$7, $Q23<=AH$8), AND($P23<=AH$7,$Q23>=AH$8)),1,0) -> 0 | ... CI23: =IF(OR((AND($P23<=CI$7,AND($Q23<=CI$8, $Q23>=CI$7))),(AND(AND($P23>=CI$7, $P23<=CI$8),$Q23>=CI$8)), AND($P23>=CI$7, $Q23<=CI$8), AND($P23<=CI$7,$Q23>=CI$8)),1,0) -> 0
A24: 2.3 | I24: 10 | J24: =IF(CheckDay>=Q24,1,IF(CheckDay<P24, 0,DAYS360(P24,CheckDay+1)/Y24)) -> 1 | K24: 0 | L24: =I24*J24/100 -> 0.1 | M24: =I24*K24/100 -> 0 | N24: =M24-L24 -> -0.1 | O24: =IF(AND(K24=0%,N24=0),"",IF(N24<0,"지연",IF(K24=100%,"종료","진행"))) -> 지연 | X24: =IF(ISBLANK(V24),"",(DAYS360(VLOOKUP(V24,$A$9:$Q$97,15,FALSE),P24)-1)) | Y24: =NETWORKDAYS(P24,Q24,진행현황_전체!C$59:C$77) -> 0 | AA24: =IF(OR((AND($P24<=AA$7,AND($Q24<=AA$8, $Q24>=AA$7))),(AND(AND($P24>=AA$7, $P24<=AA$8),$Q24>=AA$8)), AND($P24>=AA$7, $Q24<=AA$8), AND($P24<=AA$7,$Q24>=AA$8)),1,0) -> 0 | AB24: =IF(OR((AND($P24<=AB$7,AND($Q24<=AB$8, $Q24>=AB$7))),(AND(AND($P24>=AB$7, $P24<=AB$8),$Q24>=AB$8)), AND($P24>=AB$7, $Q24<=AB$8), AND($P24<=AB$7,$Q24>=AB$8)),1,0) -> 0 | AC24: =IF(OR((AND($P24<=AC$7,AND($Q24<=AC$8, $Q24>=AC$7))),(AND(AND($P24>=AC$7, $P24<=AC$8),$Q24>=AC$8)), AND($P24>=AC$7, $Q24<=AC$8), AND($P24<=AC$7,$Q24>=AC$8)),1,0) -> 0 | AD24: =IF(OR((AND($P24<=AD$7,AND($Q24<=AD$8, $Q24>=AD$7))),(AND(AND($P24>=AD$7, $P24<=AD$8),$Q24>=AD$8)), AND($P24>=AD$7, $Q24<=AD$8), AND($P24<=AD$7,$Q24>=AD$8)),1,0) -> 0 | AE24: =IF(OR((AND($P24<=AE$7,AND($Q24<=AE$8, $Q24>=AE$7))),(AND(AND($P24>=AE$7, $P24<=AE$8),$Q24>=AE$8)), AND($P24>=AE$7, $Q24<=AE$8), AND($P24<=AE$7,$Q24>=AE$8)),1,0) -> 0 | AF24: =IF(OR((AND($P24<=AF$7,AND($Q24<=AF$8, $Q24>=AF$7))),(AND(AND($P24>=AF$7, $P24<=AF$8),$Q24>=AF$8)), AND($P24>=AF$7, $Q24<=AF$8), AND($P24<=AF$7,$Q24>=AF$8)),1,0) -> 0 | AG24: =IF(OR((AND($P24<=AG$7,AND($Q24<=AG$8, $Q24>=AG$7))),(AND(AND($P24>=AG$7, $P24<=AG$8),$Q24>=AG$8)), AND($P24>=AG$7, $Q24<=AG$8), AND($P24<=AG$7,$Q24>=AG$8)),1,0) -> 0 | AH24: =IF(OR((AND($P24<=AH$7,AND($Q24<=AH$8, $Q24>=AH$7))),(AND(AND($P24>=AH$7, $P24<=AH$8),$Q24>=AH$8)), AND($P24>=AH$7, $Q24<=AH$8), AND($P24<=AH$7,$Q24>=AH$8)),1,0) -> 0 | ... CI24: =IF(OR((AND($P24<=CI$7,AND($Q24<=CI$8, $Q24>=CI$7))),(AND(AND($P24>=CI$7, $P24<=CI$8),$Q24>=CI$8)), AND($P24>=CI$7, $Q24<=CI$8), AND($P24<=CI$7,$Q24>=CI$8)),1,0) -> 0
A25: 2.4 | I25: 10 | J25: =IF(CheckDay>=Q25,1,IF(CheckDay<P25, 0,DAYS360(P25,CheckDay+1)/Y25)) -> 1 | K25: 0 | L25: =I25*J25/100 -> 0.1 | M25: =I25*K25/100 -> 0 | N25: =M25-L25 -> -0.1 | O25: =IF(AND(K25=0%,N25=0),"",IF(N25<0,"지연",IF(K25=100%,"종료","진행"))) -> 지연 | X25: =IF(ISBLANK(V25),"",(DAYS360(VLOOKUP(V25,$A$9:$Q$97,15,FALSE),P25)-1)) | Y25: =NETWORKDAYS(P25,Q25,진행현황_전체!C$59:C$77) -> 0 | AA25: =IF(OR((AND($P25<=AA$7,AND($Q25<=AA$8, $Q25>=AA$7))),(AND(AND($P25>=AA$7, $P25<=AA$8),$Q25>=AA$8)), AND($P25>=AA$7, $Q25<=AA$8), AND($P25<=AA$7,$Q25>=AA$8)),1,0) -> 0 | AB25: =IF(OR((AND($P25<=AB$7,AND($Q25<=AB$8, $Q25>=AB$7))),(AND(AND($P25>=AB$7, $P25<=AB$8),$Q25>=AB$8)), AND($P25>=AB$7, $Q25<=AB$8), AND($P25<=AB$7,$Q25>=AB$8)),1,0) -> 0 | AC25: =IF(OR((AND($P25<=AC$7,AND($Q25<=AC$8, $Q25>=AC$7))),(AND(AND($P25>=AC$7, $P25<=AC$8),$Q25>=AC$8)), AND($P25>=AC$7, $Q25<=AC$8), AND($P25<=AC$7,$Q25>=AC$8)),1,0) -> 0 | AD25: =IF(OR((AND($P25<=AD$7,AND($Q25<=AD$8, $Q25>=AD$7))),(AND(AND($P25>=AD$7, $P25<=AD$8),$Q25>=AD$8)), AND($P25>=AD$7, $Q25<=AD$8), AND($P25<=AD$7,$Q25>=AD$8)),1,0) -> 0 | AE25: =IF(OR((AND($P25<=AE$7,AND($Q25<=AE$8, $Q25>=AE$7))),(AND(AND($P25>=AE$7, $P25<=AE$8),$Q25>=AE$8)), AND($P25>=AE$7, $Q25<=AE$8), AND($P25<=AE$7,$Q25>=AE$8)),1,0) -> 0 | AF25: =IF(OR((AND($P25<=AF$7,AND($Q25<=AF$8, $Q25>=AF$7))),(AND(AND($P25>=AF$7, $P25<=AF$8),$Q25>=AF$8)), AND($P25>=AF$7, $Q25<=AF$8), AND($P25<=AF$7,$Q25>=AF$8)),1,0) -> 0 | AG25: =IF(OR((AND($P25<=AG$7,AND($Q25<=AG$8, $Q25>=AG$7))),(AND(AND($P25>=AG$7, $P25<=AG$8),$Q25>=AG$8)), AND($P25>=AG$7, $Q25<=AG$8), AND($P25<=AG$7,$Q25>=AG$8)),1,0) -> 0 | AH25: =IF(OR((AND($P25<=AH$7,AND($Q25<=AH$8, $Q25>=AH$7))),(AND(AND($P25>=AH$7, $P25<=AH$8),$Q25>=AH$8)), AND($P25>=AH$7, $Q25<=AH$8), AND($P25<=AH$7,$Q25>=AH$8)),1,0) -> 0 | ... CI25: =IF(OR((AND($P25<=CI$7,AND($Q25<=CI$8, $Q25>=CI$7))),(AND(AND($P25>=CI$7, $P25<=CI$8),$Q25>=CI$8)), AND($P25>=CI$7, $Q25<=CI$8), AND($P25<=CI$7,$Q25>=CI$8)),1,0) -> 0
A26: 2.5 | I26: 10 | J26: =IF(CheckDay>=Q26,1,IF(CheckDay<P26, 0,DAYS360(P26,CheckDay+1)/Y26)) -> 1 | K26: 0 | L26: =I26*J26/100 -> 0.1 | M26: =I26*K26/100 -> 0 | N26: =M26-L26 -> -0.1 | O26: =IF(AND(K26=0%,N26=0),"",IF(N26<0,"지연",IF(K26=100%,"종료","진행"))) -> 지연 | X26: =IF(ISBLANK(V26),"",(DAYS360(VLOOKUP(V26,$A$9:$Q$97,15,FALSE),P26)-1)) | Y26: =NETWORKDAYS(P26,Q26,진행현황_전체!C$59:C$77) -> 0 | AA26: =IF(OR((AND($P26<=AA$7,AND($Q26<=AA$8, $Q26>=AA$7))),(AND(AND($P26>=AA$7, $P26<=AA$8),$Q26>=AA$8)), AND($P26>=AA$7, $Q26<=AA$8), AND($P26<=AA$7,$Q26>=AA$8)),1,0) -> 0 | AB26: =IF(OR((AND($P26<=AB$7,AND($Q26<=AB$8, $Q26>=AB$7))),(AND(AND($P26>=AB$7, $P26<=AB$8),$Q26>=AB$8)), AND($P26>=AB$7, $Q26<=AB$8), AND($P26<=AB$7,$Q26>=AB$8)),1,0) -> 0 | AC26: =IF(OR((AND($P26<=AC$7,AND($Q26<=AC$8, $Q26>=AC$7))),(AND(AND($P26>=AC$7, $P26<=AC$8),$Q26>=AC$8)), AND($P26>=AC$7, $Q26<=AC$8), AND($P26<=AC$7,$Q26>=AC$8)),1,0) -> 0 | AD26: =IF(OR((AND($P26<=AD$7,AND($Q26<=AD$8, $Q26>=AD$7))),(AND(AND($P26>=AD$7, $P26<=AD$8),$Q26>=AD$8)), AND($P26>=AD$7, $Q26<=AD$8), AND($P26<=AD$7,$Q26>=AD$8)),1,0) -> 0 | AE26: =IF(OR((AND($P26<=AE$7,AND($Q26<=AE$8, $Q26>=AE$7))),(AND(AND($P26>=AE$7, $P26<=AE$8),$Q26>=AE$8)), AND($P26>=AE$7, $Q26<=AE$8), AND($P26<=AE$7,$Q26>=AE$8)),1,0) -> 0 | AF26: =IF(OR((AND($P26<=AF$7,AND($Q26<=AF$8, $Q26>=AF$7))),(AND(AND($P26>=AF$7, $P26<=AF$8),$Q26>=AF$8)), AND($P26>=AF$7, $Q26<=AF$8), AND($P26<=AF$7,$Q26>=AF$8)),1,0) -> 0 | AG26: =IF(OR((AND($P26<=AG$7,AND($Q26<=AG$8, $Q26>=AG$7))),(AND(AND($P26>=AG$7, $P26<=AG$8),$Q26>=AG$8)), AND($P26>=AG$7, $Q26<=AG$8), AND($P26<=AG$7,$Q26>=AG$8)),1,0) -> 0 | AH26: =IF(OR((AND($P26<=AH$7,AND($Q26<=AH$8, $Q26>=AH$7))),(AND(AND($P26>=AH$7, $P26<=AH$8),$Q26>=AH$8)), AND($P26>=AH$7, $Q26<=AH$8), AND($P26<=AH$7,$Q26>=AH$8)),1,0) -> 0 | ... CI26: =IF(OR((AND($P26<=CI$7,AND($Q26<=CI$8, $Q26>=CI$7))),(AND(AND($P26>=CI$7, $P26<=CI$8),$Q26>=CI$8)), AND($P26>=CI$7, $Q26<=CI$8), AND($P26<=CI$7,$Q26>=CI$8)),1,0) -> 0
A27: 2.6 | I27: 10 | J27: =IF(CheckDay>=Q27,1,IF(CheckDay<P27, 0,DAYS360(P27,CheckDay+1)/Y27)) -> 1 | K27: 0 | L27: =I27*J27/100 -> 0.1 | M27: =I27*K27/100 -> 0 | N27: =M27-L27 -> -0.1 | O27: =IF(AND(K27=0%,N27=0),"",IF(N27<0,"지연",IF(K27=100%,"종료","진행"))) -> 지연 | X27: =IF(ISBLANK(V27),"",(DAYS360(VLOOKUP(V27,$A$9:$Q$97,15,FALSE),P27)-1)) | Y27: =NETWORKDAYS(P27,Q27,진행현황_전체!C$59:C$77) -> 0 | AA27: =IF(OR((AND($P27<=AA$7,AND($Q27<=AA$8, $Q27>=AA$7))),(AND(AND($P27>=AA$7, $P27<=AA$8),$Q27>=AA$8)), AND($P27>=AA$7, $Q27<=AA$8), AND($P27<=AA$7,$Q27>=AA$8)),1,0) -> 0 | AB27: =IF(OR((AND($P27<=AB$7,AND($Q27<=AB$8, $Q27>=AB$7))),(AND(AND($P27>=AB$7, $P27<=AB$8),$Q27>=AB$8)), AND($P27>=AB$7, $Q27<=AB$8), AND($P27<=AB$7,$Q27>=AB$8)),1,0) -> 0 | AC27: =IF(OR((AND($P27<=AC$7,AND($Q27<=AC$8, $Q27>=AC$7))),(AND(AND($P27>=AC$7, $P27<=AC$8),$Q27>=AC$8)), AND($P27>=AC$7, $Q27<=AC$8), AND($P27<=AC$7,$Q27>=AC$8)),1,0) -> 0 | AD27: =IF(OR((AND($P27<=AD$7,AND($Q27<=AD$8, $Q27>=AD$7))),(AND(AND($P27>=AD$7, $P27<=AD$8),$Q27>=AD$8)), AND($P27>=AD$7, $Q27<=AD$8), AND($P27<=AD$7,$Q27>=AD$8)),1,0) -> 0 | AE27: =IF(OR((AND($P27<=AE$7,AND($Q27<=AE$8, $Q27>=AE$7))),(AND(AND($P27>=AE$7, $P27<=AE$8),$Q27>=AE$8)), AND($P27>=AE$7, $Q27<=AE$8), AND($P27<=AE$7,$Q27>=AE$8)),1,0) -> 0 | AF27: =IF(OR((AND($P27<=AF$7,AND($Q27<=AF$8, $Q27>=AF$7))),(AND(AND($P27>=AF$7, $P27<=AF$8),$Q27>=AF$8)), AND($P27>=AF$7, $Q27<=AF$8), AND($P27<=AF$7,$Q27>=AF$8)),1,0) -> 0 | AG27: =IF(OR((AND($P27<=AG$7,AND($Q27<=AG$8, $Q27>=AG$7))),(AND(AND($P27>=AG$7, $P27<=AG$8),$Q27>=AG$8)), AND($P27>=AG$7, $Q27<=AG$8), AND($P27<=AG$7,$Q27>=AG$8)),1,0) -> 0 | AH27: =IF(OR((AND($P27<=AH$7,AND($Q27<=AH$8, $Q27>=AH$7))),(AND(AND($P27>=AH$7, $P27<=AH$8),$Q27>=AH$8)), AND($P27>=AH$7, $Q27<=AH$8), AND($P27<=AH$7,$Q27>=AH$8)),1,0) -> 0 | ... CI27: =IF(OR((AND($P27<=CI$7,AND($Q27<=CI$8, $Q27>=CI$7))),(AND(AND($P27>=CI$7, $P27<=CI$8),$Q27>=CI$8)), AND($P27>=CI$7, $Q27<=CI$8), AND($P27<=CI$7,$Q27>=CI$8)),1,0) -> 0
A28: 2.7 | I28: 10 | J28: =IF(CheckDay>=Q28,1,IF(CheckDay<P28, 0,DAYS360(P28,CheckDay+1)/Y28)) -> 1 | K28: 0 | L28: =I28*J28/100 -> 0.1 | M28: =I28*K28/100 -> 0 | N28: =M28-L28 -> -0.1 | O28: =IF(AND(K28=0%,N28=0),"",IF(N28<0,"지연",IF(K28=100%,"종료","진행"))) -> 지연 | X28: =IF(ISBLANK(V28),"",(DAYS360(VLOOKUP(V28,$A$9:$Q$97,15,FALSE),P28)-1)) | Y28: =NETWORKDAYS(P28,Q28,진행현황_전체!C$59:C$77) -> 0 | AA28: =IF(OR((AND($P28<=AA$7,AND($Q28<=AA$8, $Q28>=AA$7))),(AND(AND($P28>=AA$7, $P28<=AA$8),$Q28>=AA$8)), AND($P28>=AA$7, $Q28<=AA$8), AND($P28<=AA$7,$Q28>=AA$8)),1,0) -> 0 | AB28: =IF(OR((AND($P28<=AB$7,AND($Q28<=AB$8, $Q28>=AB$7))),(AND(AND($P28>=AB$7, $P28<=AB$8),$Q28>=AB$8)), AND($P28>=AB$7, $Q28<=AB$8), AND($P28<=AB$7,$Q28>=AB$8)),1,0) -> 0 | AC28: =IF(OR((AND($P28<=AC$7,AND($Q28<=AC$8, $Q28>=AC$7))),(AND(AND($P28>=AC$7, $P28<=AC$8),$Q28>=AC$8)), AND($P28>=AC$7, $Q28<=AC$8), AND($P28<=AC$7,$Q28>=AC$8)),1,0) -> 0 | AD28: =IF(OR((AND($P28<=AD$7,AND($Q28<=AD$8, $Q28>=AD$7))),(AND(AND($P28>=AD$7, $P28<=AD$8),$Q28>=AD$8)), AND($P28>=AD$7, $Q28<=AD$8), AND($P28<=AD$7,$Q28>=AD$8)),1,0) -> 0 | AE28: =IF(OR((AND($P28<=AE$7,AND($Q28<=AE$8, $Q28>=AE$7))),(AND(AND($P28>=AE$7, $P28<=AE$8),$Q28>=AE$8)), AND($P28>=AE$7, $Q28<=AE$8), AND($P28<=AE$7,$Q28>=AE$8)),1,0) -> 0 | AF28: =IF(OR((AND($P28<=AF$7,AND($Q28<=AF$8, $Q28>=AF$7))),(AND(AND($P28>=AF$7, $P28<=AF$8),$Q28>=AF$8)), AND($P28>=AF$7, $Q28<=AF$8), AND($P28<=AF$7,$Q28>=AF$8)),1,0) -> 0 | AG28: =IF(OR((AND($P28<=AG$7,AND($Q28<=AG$8, $Q28>=AG$7))),(AND(AND($P28>=AG$7, $P28<=AG$8),$Q28>=AG$8)), AND($P28>=AG$7, $Q28<=AG$8), AND($P28<=AG$7,$Q28>=AG$8)),1,0) -> 0 | AH28: =IF(OR((AND($P28<=AH$7,AND($Q28<=AH$8, $Q28>=AH$7))),(AND(AND($P28>=AH$7, $P28<=AH$8),$Q28>=AH$8)), AND($P28>=AH$7, $Q28<=AH$8), AND($P28<=AH$7,$Q28>=AH$8)),1,0) -> 0 | ... CI28: =IF(OR((AND($P28<=CI$7,AND($Q28<=CI$8, $Q28>=CI$7))),(AND(AND($P28>=CI$7, $P28<=CI$8),$Q28>=CI$8)), AND($P28>=CI$7, $Q28<=CI$8), AND($P28<=CI$7,$Q28>=CI$8)),1,0) -> 0
A29: 2.8 | I29: 10 | J29: =IF(CheckDay>=Q29,1,IF(CheckDay<P29, 0,DAYS360(P29,CheckDay+1)/Y29)) -> 1 | K29: 0 | L29: =I29*J29/100 -> 0.1 | M29: =I29*K29/100 -> 0 | N29: =M29-L29 -> -0.1 | O29: =IF(AND(K29=0%,N29=0),"",IF(N29<0,"지연",IF(K29=100%,"종료","진행"))) -> 지연 | X29: =IF(ISBLANK(V29),"",(DAYS360(VLOOKUP(V29,$A$9:$Q$97,15,FALSE),P29)-1)) | Y29: =NETWORKDAYS(P29,Q29,진행현황_전체!C$59:C$77) -> 0 | AA29: =IF(OR((AND($P29<=AA$7,AND($Q29<=AA$8, $Q29>=AA$7))),(AND(AND($P29>=AA$7, $P29<=AA$8),$Q29>=AA$8)), AND($P29>=AA$7, $Q29<=AA$8), AND($P29<=AA$7,$Q29>=AA$8)),1,0) -> 0 | AB29: =IF(OR((AND($P29<=AB$7,AND($Q29<=AB$8, $Q29>=AB$7))),(AND(AND($P29>=AB$7, $P29<=AB$8),$Q29>=AB$8)), AND($P29>=AB$7, $Q29<=AB$8), AND($P29<=AB$7,$Q29>=AB$8)),1,0) -> 0 | AC29: =IF(OR((AND($P29<=AC$7,AND($Q29<=AC$8, $Q29>=AC$7))),(AND(AND($P29>=AC$7, $P29<=AC$8),$Q29>=AC$8)), AND($P29>=AC$7, $Q29<=AC$8), AND($P29<=AC$7,$Q29>=AC$8)),1,0) -> 0 | AD29: =IF(OR((AND($P29<=AD$7,AND($Q29<=AD$8, $Q29>=AD$7))),(AND(AND($P29>=AD$7, $P29<=AD$8),$Q29>=AD$8)), AND($P29>=AD$7, $Q29<=AD$8), AND($P29<=AD$7,$Q29>=AD$8)),1,0) -> 0 | AE29: =IF(OR((AND($P29<=AE$7,AND($Q29<=AE$8, $Q29>=AE$7))),(AND(AND($P29>=AE$7, $P29<=AE$8),$Q29>=AE$8)), AND($P29>=AE$7, $Q29<=AE$8), AND($P29<=AE$7,$Q29>=AE$8)),1,0) -> 0 | AF29: =IF(OR((AND($P29<=AF$7,AND($Q29<=AF$8, $Q29>=AF$7))),(AND(AND($P29>=AF$7, $P29<=AF$8),$Q29>=AF$8)), AND($P29>=AF$7, $Q29<=AF$8), AND($P29<=AF$7,$Q29>=AF$8)),1,0) -> 0 | AG29: =IF(OR((AND($P29<=AG$7,AND($Q29<=AG$8, $Q29>=AG$7))),(AND(AND($P29>=AG$7, $P29<=AG$8),$Q29>=AG$8)), AND($P29>=AG$7, $Q29<=AG$8), AND($P29<=AG$7,$Q29>=AG$8)),1,0) -> 0 | AH29: =IF(OR((AND($P29<=AH$7,AND($Q29<=AH$8, $Q29>=AH$7))),(AND(AND($P29>=AH$7, $P29<=AH$8),$Q29>=AH$8)), AND($P29>=AH$7, $Q29<=AH$8), AND($P29<=AH$7,$Q29>=AH$8)),1,0) -> 0 | ... CI29: =IF(OR((AND($P29<=CI$7,AND($Q29<=CI$8, $Q29>=CI$7))),(AND(AND($P29>=CI$7, $P29<=CI$8),$Q29>=CI$8)), AND($P29>=CI$7, $Q29<=CI$8), AND($P29<=CI$7,$Q29>=CI$8)),1,0) -> 0
A30: 2.9 | I30: 10 | J30: =IF(CheckDay>=Q30,1,IF(CheckDay<P30, 0,DAYS360(P30,CheckDay+1)/Y30)) -> 1 | K30: 0 | L30: =I30*J30/100 -> 0.1 | M30: =I30*K30/100 -> 0 | N30: =M30-L30 -> -0.1 | O30: =IF(AND(K30=0%,N30=0),"",IF(N30<0,"지연",IF(K30=100%,"종료","진행"))) -> 지연 | X30: =IF(ISBLANK(V30),"",(DAYS360(VLOOKUP(V30,$A$9:$Q$97,15,FALSE),P30)-1)) | Y30: =NETWORKDAYS(P30,Q30,진행현황_전체!C$59:C$77) -> 0 | AA30: =IF(OR((AND($P30<=AA$7,AND($Q30<=AA$8, $Q30>=AA$7))),(AND(AND($P30>=AA$7, $P30<=AA$8),$Q30>=AA$8)), AND($P30>=AA$7, $Q30<=AA$8), AND($P30<=AA$7,$Q30>=AA$8)),1,0) -> 0 | AB30: =IF(OR((AND($P30<=AB$7,AND($Q30<=AB$8, $Q30>=AB$7))),(AND(AND($P30>=AB$7, $P30<=AB$8),$Q30>=AB$8)), AND($P30>=AB$7, $Q30<=AB$8), AND($P30<=AB$7,$Q30>=AB$8)),1,0) -> 0 | AC30: =IF(OR((AND($P30<=AC$7,AND($Q30<=AC$8, $Q30>=AC$7))),(AND(AND($P30>=AC$7, $P30<=AC$8),$Q30>=AC$8)), AND($P30>=AC$7, $Q30<=AC$8), AND($P30<=AC$7,$Q30>=AC$8)),1,0) -> 0 | AD30: =IF(OR((AND($P30<=AD$7,AND($Q30<=AD$8, $Q30>=AD$7))),(AND(AND($P30>=AD$7, $P30<=AD$8),$Q30>=AD$8)), AND($P30>=AD$7, $Q30<=AD$8), AND($P30<=AD$7,$Q30>=AD$8)),1,0) -> 0 | AE30: =IF(OR((AND($P30<=AE$7,AND($Q30<=AE$8, $Q30>=AE$7))),(AND(AND($P30>=AE$7, $P30<=AE$8),$Q30>=AE$8)), AND($P30>=AE$7, $Q30<=AE$8), AND($P30<=AE$7,$Q30>=AE$8)),1,0) -> 0 | AF30: =IF(OR((AND($P30<=AF$7,AND($Q30<=AF$8, $Q30>=AF$7))),(AND(AND($P30>=AF$7, $P30<=AF$8),$Q30>=AF$8)), AND($P30>=AF$7, $Q30<=AF$8), AND($P30<=AF$7,$Q30>=AF$8)),1,0) -> 0 | AG30: =IF(OR((AND($P30<=AG$7,AND($Q30<=AG$8, $Q30>=AG$7))),(AND(AND($P30>=AG$7, $P30<=AG$8),$Q30>=AG$8)), AND($P30>=AG$7, $Q30<=AG$8), AND($P30<=AG$7,$Q30>=AG$8)),1,0) -> 0 | AH30: =IF(OR((AND($P30<=AH$7,AND($Q30<=AH$8, $Q30>=AH$7))),(AND(AND($P30>=AH$7, $P30<=AH$8),$Q30>=AH$8)), AND($P30>=AH$7, $Q30<=AH$8), AND($P30<=AH$7,$Q30>=AH$8)),1,0) -> 0 | ... CI30: =IF(OR((AND($P30<=CI$7,AND($Q30<=CI$8, $Q30>=CI$7))),(AND(AND($P30>=CI$7, $P30<=CI$8),$Q30>=CI$8)), AND($P30>=CI$7, $Q30<=CI$8), AND($P30<=CI$7,$Q30>=CI$8)),1,0) -> 0
A31: 2.10 | I31: 10 | J31: =IF(CheckDay>=Q31,1,IF(CheckDay<P31, 0,DAYS360(P31,CheckDay+1)/Y31)) -> 1 | K31: 0 | L31: =I31*J31/100 -> 0.1 | M31: =I31*K31/100 -> 0 | N31: =M31-L31 -> -0.1 | O31: =IF(AND(K31=0%,N31=0),"",IF(N31<0,"지연",IF(K31=100%,"종료","진행"))) -> 지연 | X31: =IF(ISBLANK(V31),"",(DAYS360(VLOOKUP(V31,$A$9:$Q$97,15,FALSE),P31)-1)) | Y31: =NETWORKDAYS(P31,Q31,진행현황_전체!C$59:C$77) -> 0 | AA31: =IF(OR((AND($P31<=AA$7,AND($Q31<=AA$8, $Q31>=AA$7))),(AND(AND($P31>=AA$7, $P31<=AA$8),$Q31>=AA$8)), AND($P31>=AA$7, $Q31<=AA$8), AND($P31<=AA$7,$Q31>=AA$8)),1,0) -> 0 | AB31: =IF(OR((AND($P31<=AB$7,AND($Q31<=AB$8, $Q31>=AB$7))),(AND(AND($P31>=AB$7, $P31<=AB$8),$Q31>=AB$8)), AND($P31>=AB$7, $Q31<=AB$8), AND($P31<=AB$7,$Q31>=AB$8)),1,0) -> 0 | AC31: =IF(OR((AND($P31<=AC$7,AND($Q31<=AC$8, $Q31>=AC$7))),(AND(AND($P31>=AC$7, $P31<=AC$8),$Q31>=AC$8)), AND($P31>=AC$7, $Q31<=AC$8), AND($P31<=AC$7,$Q31>=AC$8)),1,0) -> 0 | AD31: =IF(OR((AND($P31<=AD$7,AND($Q31<=AD$8, $Q31>=AD$7))),(AND(AND($P31>=AD$7, $P31<=AD$8),$Q31>=AD$8)), AND($P31>=AD$7, $Q31<=AD$8), AND($P31<=AD$7,$Q31>=AD$8)),1,0) -> 0 | AE31: =IF(OR((AND($P31<=AE$7,AND($Q31<=AE$8, $Q31>=AE$7))),(AND(AND($P31>=AE$7, $P31<=AE$8),$Q31>=AE$8)), AND($P31>=AE$7, $Q31<=AE$8), AND($P31<=AE$7,$Q31>=AE$8)),1,0) -> 0 | AF31: =IF(OR((AND($P31<=AF$7,AND($Q31<=AF$8, $Q31>=AF$7))),(AND(AND($P31>=AF$7, $P31<=AF$8),$Q31>=AF$8)), AND($P31>=AF$7, $Q31<=AF$8), AND($P31<=AF$7,$Q31>=AF$8)),1,0) -> 0 | AG31: =IF(OR((AND($P31<=AG$7,AND($Q31<=AG$8, $Q31>=AG$7))),(AND(AND($P31>=AG$7, $P31<=AG$8),$Q31>=AG$8)), AND($P31>=AG$7, $Q31<=AG$8), AND($P31<=AG$7,$Q31>=AG$8)),1,0) -> 0 | AH31: =IF(OR((AND($P31<=AH$7,AND($Q31<=AH$8, $Q31>=AH$7))),(AND(AND($P31>=AH$7, $P31<=AH$8),$Q31>=AH$8)), AND($P31>=AH$7, $Q31<=AH$8), AND($P31<=AH$7,$Q31>=AH$8)),1,0) -> 0 | ... CI31: =IF(OR((AND($P31<=CI$7,AND($Q31<=CI$8, $Q31>=CI$7))),(AND(AND($P31>=CI$7, $P31<=CI$8),$Q31>=CI$8)), AND($P31>=CI$7, $Q31<=CI$8), AND($P31<=CI$7,$Q31>=CI$8)),1,0) -> 0
